2020-06-19 21:56:08,812 -- [run_test.py-->line:10] - INFO: --------------------开始执行案例-------------------
2020-06-19 21:57:53,648 -- [run_test.py-->line:10] - INFO: --------------------开始执行案例-------------------
2020-06-19 21:57:54,545 -- [run_test.py-->line:22] - INFO: ------------------测试案例执行结束--------------------
2020-06-19 21:58:51,752 -- [run_test.py-->line:10] - INFO: --------------------开始执行案例-------------------
2020-06-19 21:58:52,429 -- [run_test.py-->line:22] - INFO: ------------------测试案例执行结束--------------------
2020-06-19 22:00:34,651 -- [run_test.py-->line:10] - INFO: --------------------开始执行案例-------------------
2020-06-19 22:00:35,357 -- [run_test.py-->line:22] - INFO: ------------------测试案例执行结束--------------------
2020-06-19 22:14:38,819 -- [test_register.py-->line:50] - ERROR: 用例---注册成功-带注册名----执行未通过
2020-06-19 22:14:38,819 -- [test_register.py-->line:51] - DEBUG: 预期结果为：{'code': 0, 'msg': 'OK'}
2020-06-19 22:14:38,819 -- [test_register.py-->line:52] - DEBUG: 实际结果为：{'code': 2, 'msg': '账号已存在', 'data': None, 'copyright': 'Copyright 柠檬班 © 2017-2020 湖南省零檬信息技术有限公司 All Rights Reserved'}
2020-06-19 22:14:38,819 -- [test_register.py-->line:53] - ERROR:  :: 0 != 2
Traceback (most recent call last):
  File "C:\Program Files\JetBrains\PyCharm Community Edition 2019.3.4\plugins\python-ce\helpers\pycharm\teamcity\diff_tools.py", line 32, in _patched_equals
    old(self, first, second, msg)
  File "D:\Program Files\Python38\lib\unittest\case.py", line 912, in assertEqual
    assertion_func(first, second, msg=msg)
  File "D:\Program Files\Python38\lib\unittest\case.py", line 905, in _baseAssertEqual
    raise self.failureException(msg)
AssertionError: 0 != 2

During handling of the above exception, another exception occurred:

Traceback (most recent call last):
  File "D:\PychramCode\auto_api_test\testcases\test_register.py", line 46, in test_register
    self.assertEqual(expected["code"], res["code"])
  File "C:\Program Files\JetBrains\PyCharm Community Edition 2019.3.4\plugins\python-ce\helpers\pycharm\teamcity\diff_tools.py", line 38, in _patched_equals
    raise error
teamcity.diff_tools.EqualsAssertionError:  :: 0 != 2
2020-06-19 22:14:38,915 -- [test_register.py-->line:50] - ERROR: 用例---成功-不带用户名----执行未通过
2020-06-19 22:14:38,915 -- [test_register.py-->line:51] - DEBUG: 预期结果为：{'code': 0, 'msg': 'OK'}
2020-06-19 22:14:38,915 -- [test_register.py-->line:52] - DEBUG: 实际结果为：{'code': 2, 'msg': '账号已存在', 'data': None, 'copyright': 'Copyright 柠檬班 © 2017-2020 湖南省零檬信息技术有限公司 All Rights Reserved'}
2020-06-19 22:14:38,915 -- [test_register.py-->line:53] - ERROR:  :: 0 != 2
Traceback (most recent call last):
  File "C:\Program Files\JetBrains\PyCharm Community Edition 2019.3.4\plugins\python-ce\helpers\pycharm\teamcity\diff_tools.py", line 32, in _patched_equals
    old(self, first, second, msg)
  File "D:\Program Files\Python38\lib\unittest\case.py", line 912, in assertEqual
    assertion_func(first, second, msg=msg)
  File "D:\Program Files\Python38\lib\unittest\case.py", line 905, in _baseAssertEqual
    raise self.failureException(msg)
AssertionError: 0 != 2

During handling of the above exception, another exception occurred:

Traceback (most recent call last):
  File "D:\PychramCode\auto_api_test\testcases\test_register.py", line 46, in test_register
    self.assertEqual(expected["code"], res["code"])
  File "C:\Program Files\JetBrains\PyCharm Community Edition 2019.3.4\plugins\python-ce\helpers\pycharm\teamcity\diff_tools.py", line 38, in _patched_equals
    raise error
teamcity.diff_tools.EqualsAssertionError:  :: 0 != 2
2020-06-19 22:14:38,997 -- [test_register.py-->line:59] - INFO: 用例---不输入手机号----执行通过
2020-06-19 22:14:39,088 -- [test_register.py-->line:59] - INFO: 用例---手机号长度10位----执行通过
2020-06-19 22:14:39,184 -- [test_register.py-->line:59] - INFO: 用例---手机号长度12位----执行通过
2020-06-19 22:14:39,279 -- [test_register.py-->line:59] - INFO: 用例---手机号含有非法字符----执行通过
2020-06-19 22:14:39,397 -- [test_register.py-->line:59] - INFO: 用例---已注册过的手机号----执行通过
2020-06-19 22:14:39,499 -- [test_register.py-->line:59] - INFO: 用例---密码7位----执行通过
2020-06-19 22:14:39,601 -- [test_register.py-->line:59] - INFO: 用例---密码17位----执行通过
2020-06-19 22:14:39,692 -- [test_register.py-->line:59] - INFO: 用例---不输入密码----执行通过
2020-06-19 22:14:39,785 -- [test_register.py-->line:59] - INFO: 用例---注册名11位----执行通过
2020-06-19 22:14:39,875 -- [test_register.py-->line:59] - INFO: 用例---类型输入非0，1内容----执行通过
2020-06-19 22:14:39,986 -- [test_register.py-->line:50] - ERROR: 用例---不输入类型----执行未通过
2020-06-19 22:14:39,986 -- [test_register.py-->line:51] - DEBUG: 预期结果为：{'code': 0, 'msg': 'OK'}
2020-06-19 22:14:39,986 -- [test_register.py-->line:52] - DEBUG: 实际结果为：{'code': 2, 'msg': '账号已存在', 'data': None, 'copyright': 'Copyright 柠檬班 © 2017-2020 湖南省零檬信息技术有限公司 All Rights Reserved'}
2020-06-19 22:14:39,986 -- [test_register.py-->line:53] - ERROR:  :: 0 != 2
Traceback (most recent call last):
  File "C:\Program Files\JetBrains\PyCharm Community Edition 2019.3.4\plugins\python-ce\helpers\pycharm\teamcity\diff_tools.py", line 32, in _patched_equals
    old(self, first, second, msg)
  File "D:\Program Files\Python38\lib\unittest\case.py", line 912, in assertEqual
    assertion_func(first, second, msg=msg)
  File "D:\Program Files\Python38\lib\unittest\case.py", line 905, in _baseAssertEqual
    raise self.failureException(msg)
AssertionError: 0 != 2

During handling of the above exception, another exception occurred:

Traceback (most recent call last):
  File "D:\PychramCode\auto_api_test\testcases\test_register.py", line 46, in test_register
    self.assertEqual(expected["code"], res["code"])
  File "C:\Program Files\JetBrains\PyCharm Community Edition 2019.3.4\plugins\python-ce\helpers\pycharm\teamcity\diff_tools.py", line 38, in _patched_equals
    raise error
teamcity.diff_tools.EqualsAssertionError:  :: 0 != 2
2020-06-19 22:22:12,633 -- [test_register.py-->line:50] - ERROR: 用例---注册成功-带注册名----执行未通过
2020-06-19 22:22:12,633 -- [test_register.py-->line:51] - DEBUG: 预期结果为：{'code': 0, 'msg': 'OK'}
2020-06-19 22:22:12,633 -- [test_register.py-->line:52] - DEBUG: 实际结果为：{'code': 2, 'msg': '账号已存在', 'data': None, 'copyright': 'Copyright 柠檬班 © 2017-2020 湖南省零檬信息技术有限公司 All Rights Reserved'}
2020-06-19 22:22:12,633 -- [test_register.py-->line:53] - ERROR:  :: 0 != 2
Traceback (most recent call last):
  File "C:\Program Files\JetBrains\PyCharm Community Edition 2019.3.4\plugins\python-ce\helpers\pycharm\teamcity\diff_tools.py", line 32, in _patched_equals
    old(self, first, second, msg)
  File "D:\Program Files\Python38\lib\unittest\case.py", line 912, in assertEqual
    assertion_func(first, second, msg=msg)
  File "D:\Program Files\Python38\lib\unittest\case.py", line 905, in _baseAssertEqual
    raise self.failureException(msg)
AssertionError: 0 != 2

During handling of the above exception, another exception occurred:

Traceback (most recent call last):
  File "D:\PychramCode\auto_api_test\testcases\test_register.py", line 46, in test_register
    self.assertEqual(expected["code"], res["code"])
  File "C:\Program Files\JetBrains\PyCharm Community Edition 2019.3.4\plugins\python-ce\helpers\pycharm\teamcity\diff_tools.py", line 38, in _patched_equals
    raise error
teamcity.diff_tools.EqualsAssertionError:  :: 0 != 2
2020-06-19 22:22:12,783 -- [test_register.py-->line:50] - ERROR: 用例---成功-不带用户名----执行未通过
2020-06-19 22:22:12,783 -- [test_register.py-->line:51] - DEBUG: 预期结果为：{'code': 0, 'msg': 'OK'}
2020-06-19 22:22:12,783 -- [test_register.py-->line:52] - DEBUG: 实际结果为：{'code': 2, 'msg': '账号已存在', 'data': None, 'copyright': 'Copyright 柠檬班 © 2017-2020 湖南省零檬信息技术有限公司 All Rights Reserved'}
2020-06-19 22:22:12,783 -- [test_register.py-->line:53] - ERROR:  :: 0 != 2
Traceback (most recent call last):
  File "C:\Program Files\JetBrains\PyCharm Community Edition 2019.3.4\plugins\python-ce\helpers\pycharm\teamcity\diff_tools.py", line 32, in _patched_equals
    old(self, first, second, msg)
  File "D:\Program Files\Python38\lib\unittest\case.py", line 912, in assertEqual
    assertion_func(first, second, msg=msg)
  File "D:\Program Files\Python38\lib\unittest\case.py", line 905, in _baseAssertEqual
    raise self.failureException(msg)
AssertionError: 0 != 2

During handling of the above exception, another exception occurred:

Traceback (most recent call last):
  File "D:\PychramCode\auto_api_test\testcases\test_register.py", line 46, in test_register
    self.assertEqual(expected["code"], res["code"])
  File "C:\Program Files\JetBrains\PyCharm Community Edition 2019.3.4\plugins\python-ce\helpers\pycharm\teamcity\diff_tools.py", line 38, in _patched_equals
    raise error
teamcity.diff_tools.EqualsAssertionError:  :: 0 != 2
2020-06-19 22:22:12,900 -- [test_register.py-->line:59] - INFO: 用例---不输入手机号----执行通过
2020-06-19 22:22:13,016 -- [test_register.py-->line:59] - INFO: 用例---手机号长度10位----执行通过
2020-06-19 22:22:13,123 -- [test_register.py-->line:59] - INFO: 用例---手机号长度12位----执行通过
2020-06-19 22:22:13,236 -- [test_register.py-->line:59] - INFO: 用例---手机号含有非法字符----执行通过
2020-06-19 22:22:13,370 -- [test_register.py-->line:59] - INFO: 用例---已注册过的手机号----执行通过
2020-06-19 22:22:13,484 -- [test_register.py-->line:59] - INFO: 用例---密码7位----执行通过
2020-06-19 22:22:13,604 -- [test_register.py-->line:59] - INFO: 用例---密码17位----执行通过
2020-06-19 22:22:13,726 -- [test_register.py-->line:59] - INFO: 用例---不输入密码----执行通过
2020-06-19 22:22:13,846 -- [test_register.py-->line:59] - INFO: 用例---注册名11位----执行通过
2020-06-19 22:22:13,968 -- [test_register.py-->line:59] - INFO: 用例---类型输入非0，1内容----执行通过
2020-06-19 22:22:14,108 -- [test_register.py-->line:50] - ERROR: 用例---不输入类型----执行未通过
2020-06-19 22:22:14,108 -- [test_register.py-->line:51] - DEBUG: 预期结果为：{'code': 0, 'msg': 'OK'}
2020-06-19 22:22:14,108 -- [test_register.py-->line:52] - DEBUG: 实际结果为：{'code': 2, 'msg': '账号已存在', 'data': None, 'copyright': 'Copyright 柠檬班 © 2017-2020 湖南省零檬信息技术有限公司 All Rights Reserved'}
2020-06-19 22:22:14,108 -- [test_register.py-->line:53] - ERROR:  :: 0 != 2
Traceback (most recent call last):
  File "C:\Program Files\JetBrains\PyCharm Community Edition 2019.3.4\plugins\python-ce\helpers\pycharm\teamcity\diff_tools.py", line 32, in _patched_equals
    old(self, first, second, msg)
  File "D:\Program Files\Python38\lib\unittest\case.py", line 912, in assertEqual
    assertion_func(first, second, msg=msg)
  File "D:\Program Files\Python38\lib\unittest\case.py", line 905, in _baseAssertEqual
    raise self.failureException(msg)
AssertionError: 0 != 2

During handling of the above exception, another exception occurred:

Traceback (most recent call last):
  File "D:\PychramCode\auto_api_test\testcases\test_register.py", line 46, in test_register
    self.assertEqual(expected["code"], res["code"])
  File "C:\Program Files\JetBrains\PyCharm Community Edition 2019.3.4\plugins\python-ce\helpers\pycharm\teamcity\diff_tools.py", line 38, in _patched_equals
    raise error
teamcity.diff_tools.EqualsAssertionError:  :: 0 != 2
2020-06-19 22:22:33,181 -- [run_test.py-->line:10] - INFO: --------------------开始执行案例-------------------
2020-06-19 22:22:33,995 -- [test_register.py-->line:50] - ERROR: 用例---注册成功-带注册名----执行未通过
2020-06-19 22:22:33,995 -- [test_register.py-->line:51] - DEBUG: 预期结果为：{'code': 0, 'msg': 'OK'}
2020-06-19 22:22:33,995 -- [test_register.py-->line:52] - DEBUG: 实际结果为：{'code': 2, 'msg': '账号已存在', 'data': None, 'copyright': 'Copyright 柠檬班 © 2017-2020 湖南省零檬信息技术有限公司 All Rights Reserved'}
2020-06-19 22:22:33,995 -- [test_register.py-->line:53] - ERROR: 0 != 2
Traceback (most recent call last):
  File "D:\PychramCode\auto_api_test\testcases\test_register.py", line 46, in test_register
    self.assertEqual(expected["code"], res["code"])
  File "D:\Program Files\Python38\lib\unittest\case.py", line 912, in assertEqual
    assertion_func(first, second, msg=msg)
  File "D:\Program Files\Python38\lib\unittest\case.py", line 905, in _baseAssertEqual
    raise self.failureException(msg)
AssertionError: 0 != 2
2020-06-19 22:22:34,142 -- [test_register.py-->line:50] - ERROR: 用例---成功-不带用户名----执行未通过
2020-06-19 22:22:34,142 -- [test_register.py-->line:51] - DEBUG: 预期结果为：{'code': 0, 'msg': 'OK'}
2020-06-19 22:22:34,142 -- [test_register.py-->line:52] - DEBUG: 实际结果为：{'code': 2, 'msg': '账号已存在', 'data': None, 'copyright': 'Copyright 柠檬班 © 2017-2020 湖南省零檬信息技术有限公司 All Rights Reserved'}
2020-06-19 22:22:34,142 -- [test_register.py-->line:53] - ERROR: 0 != 2
Traceback (most recent call last):
  File "D:\PychramCode\auto_api_test\testcases\test_register.py", line 46, in test_register
    self.assertEqual(expected["code"], res["code"])
  File "D:\Program Files\Python38\lib\unittest\case.py", line 912, in assertEqual
    assertion_func(first, second, msg=msg)
  File "D:\Program Files\Python38\lib\unittest\case.py", line 905, in _baseAssertEqual
    raise self.failureException(msg)
AssertionError: 0 != 2
2020-06-19 22:22:34,259 -- [test_register.py-->line:59] - INFO: 用例---不输入手机号----执行通过
2020-06-19 22:22:34,383 -- [test_register.py-->line:59] - INFO: 用例---手机号长度10位----执行通过
2020-06-19 22:22:34,498 -- [test_register.py-->line:59] - INFO: 用例---手机号长度12位----执行通过
2020-06-19 22:22:34,619 -- [test_register.py-->line:59] - INFO: 用例---手机号含有非法字符----执行通过
2020-06-19 22:22:34,762 -- [test_register.py-->line:59] - INFO: 用例---已注册过的手机号----执行通过
2020-06-19 22:22:34,874 -- [test_register.py-->line:59] - INFO: 用例---密码7位----执行通过
2020-06-19 22:22:34,994 -- [test_register.py-->line:59] - INFO: 用例---密码17位----执行通过
2020-06-19 22:22:35,110 -- [test_register.py-->line:59] - INFO: 用例---不输入密码----执行通过
2020-06-19 22:22:35,232 -- [test_register.py-->line:59] - INFO: 用例---注册名11位----执行通过
2020-06-19 22:22:35,352 -- [test_register.py-->line:59] - INFO: 用例---类型输入非0，1内容----执行通过
2020-06-19 22:22:35,482 -- [test_register.py-->line:50] - ERROR: 用例---不输入类型----执行未通过
2020-06-19 22:22:35,483 -- [test_register.py-->line:51] - DEBUG: 预期结果为：{'code': 0, 'msg': 'OK'}
2020-06-19 22:22:35,483 -- [test_register.py-->line:52] - DEBUG: 实际结果为：{'code': 2, 'msg': '账号已存在', 'data': None, 'copyright': 'Copyright 柠檬班 © 2017-2020 湖南省零檬信息技术有限公司 All Rights Reserved'}
2020-06-19 22:22:35,483 -- [test_register.py-->line:53] - ERROR: 0 != 2
Traceback (most recent call last):
  File "D:\PychramCode\auto_api_test\testcases\test_register.py", line 46, in test_register
    self.assertEqual(expected["code"], res["code"])
  File "D:\Program Files\Python38\lib\unittest\case.py", line 912, in assertEqual
    assertion_func(first, second, msg=msg)
  File "D:\Program Files\Python38\lib\unittest\case.py", line 905, in _baseAssertEqual
    raise self.failureException(msg)
AssertionError: 0 != 2
2020-06-19 22:22:35,538 -- [run_test.py-->line:22] - INFO: ------------------测试案例执行结束--------------------
2020-06-19 22:25:02,577 -- [run_test.py-->line:10] - INFO: --------------------开始执行案例-------------------
2020-06-19 22:25:03,408 -- [test_register.py-->line:50] - ERROR: 用例---注册成功-带注册名----执行未通过
2020-06-19 22:25:03,408 -- [test_register.py-->line:51] - DEBUG: 预期结果为：{'code': 0, 'msg': 'OK'}
2020-06-19 22:25:03,408 -- [test_register.py-->line:52] - DEBUG: 实际结果为：{'code': 2, 'msg': '账号已存在', 'data': None, 'copyright': 'Copyright 柠檬班 © 2017-2020 湖南省零檬信息技术有限公司 All Rights Reserved'}
2020-06-19 22:25:03,408 -- [test_register.py-->line:53] - ERROR: 0 != 2
Traceback (most recent call last):
  File "D:\PychramCode\auto_api_test\testcases\test_register.py", line 46, in test_register
    self.assertEqual(expected["code"], res["code"])
  File "D:\Program Files\Python38\lib\unittest\case.py", line 912, in assertEqual
    assertion_func(first, second, msg=msg)
  File "D:\Program Files\Python38\lib\unittest\case.py", line 905, in _baseAssertEqual
    raise self.failureException(msg)
AssertionError: 0 != 2
2020-06-19 22:25:03,546 -- [test_register.py-->line:50] - ERROR: 用例---成功-不带用户名----执行未通过
2020-06-19 22:25:03,546 -- [test_register.py-->line:51] - DEBUG: 预期结果为：{'code': 0, 'msg': 'OK'}
2020-06-19 22:25:03,547 -- [test_register.py-->line:52] - DEBUG: 实际结果为：{'code': 2, 'msg': '账号已存在', 'data': None, 'copyright': 'Copyright 柠檬班 © 2017-2020 湖南省零檬信息技术有限公司 All Rights Reserved'}
2020-06-19 22:25:03,547 -- [test_register.py-->line:53] - ERROR: 0 != 2
Traceback (most recent call last):
  File "D:\PychramCode\auto_api_test\testcases\test_register.py", line 46, in test_register
    self.assertEqual(expected["code"], res["code"])
  File "D:\Program Files\Python38\lib\unittest\case.py", line 912, in assertEqual
    assertion_func(first, second, msg=msg)
  File "D:\Program Files\Python38\lib\unittest\case.py", line 905, in _baseAssertEqual
    raise self.failureException(msg)
AssertionError: 0 != 2
2020-06-19 22:25:03,667 -- [test_register.py-->line:59] - INFO: 用例---不输入手机号----执行通过
2020-06-19 22:25:03,786 -- [test_register.py-->line:59] - INFO: 用例---手机号长度10位----执行通过
2020-06-19 22:25:03,902 -- [test_register.py-->line:59] - INFO: 用例---手机号长度12位----执行通过
2020-06-19 22:25:04,024 -- [test_register.py-->line:59] - INFO: 用例---手机号含有非法字符----执行通过
2020-06-19 22:25:04,168 -- [test_register.py-->line:59] - INFO: 用例---已注册过的手机号----执行通过
2020-06-19 22:25:04,296 -- [test_register.py-->line:59] - INFO: 用例---密码7位----执行通过
2020-06-19 22:25:04,422 -- [test_register.py-->line:59] - INFO: 用例---密码17位----执行通过
2020-06-19 22:25:04,544 -- [test_register.py-->line:59] - INFO: 用例---不输入密码----执行通过
2020-06-19 22:25:04,667 -- [test_register.py-->line:59] - INFO: 用例---注册名11位----执行通过
2020-06-19 22:25:04,795 -- [test_register.py-->line:59] - INFO: 用例---类型输入非0，1内容----执行通过
2020-06-19 22:25:04,929 -- [test_register.py-->line:50] - ERROR: 用例---不输入类型----执行未通过
2020-06-19 22:25:04,929 -- [test_register.py-->line:51] - DEBUG: 预期结果为：{'code': 0, 'msg': 'OK'}
2020-06-19 22:25:04,929 -- [test_register.py-->line:52] - DEBUG: 实际结果为：{'code': 2, 'msg': '账号已存在', 'data': None, 'copyright': 'Copyright 柠檬班 © 2017-2020 湖南省零檬信息技术有限公司 All Rights Reserved'}
2020-06-19 22:25:04,929 -- [test_register.py-->line:53] - ERROR: 0 != 2
Traceback (most recent call last):
  File "D:\PychramCode\auto_api_test\testcases\test_register.py", line 46, in test_register
    self.assertEqual(expected["code"], res["code"])
  File "D:\Program Files\Python38\lib\unittest\case.py", line 912, in assertEqual
    assertion_func(first, second, msg=msg)
  File "D:\Program Files\Python38\lib\unittest\case.py", line 905, in _baseAssertEqual
    raise self.failureException(msg)
AssertionError: 0 != 2
2020-06-19 22:25:04,982 -- [run_test.py-->line:22] - INFO: ------------------测试案例执行结束--------------------
2020-06-19 22:37:44,023 -- [run_test.py-->line:10] - INFO: --------------------开始执行案例-------------------
2020-06-19 22:37:44,905 -- [test_login.py-->line:59] - INFO: 用例---登录成功----执行通过
2020-06-19 22:37:45,025 -- [test_login.py-->line:59] - INFO: 用例---手机号为空----执行通过
2020-06-19 22:37:45,153 -- [test_login.py-->line:59] - INFO: 用例---密码为空----执行通过
2020-06-19 22:37:45,296 -- [test_login.py-->line:59] - INFO: 用例---手机号未注册----执行通过
2020-06-19 22:37:45,438 -- [test_login.py-->line:59] - INFO: 用例---密码错误----执行通过
2020-06-19 22:37:45,559 -- [test_login.py-->line:59] - INFO: 用例---手机号格式错误----执行通过
2020-06-19 22:37:45,706 -- [test_register.py-->line:50] - ERROR: 用例---注册成功-带注册名----执行未通过
2020-06-19 22:37:45,706 -- [test_register.py-->line:51] - DEBUG: 预期结果为：{'code': 0, 'msg': 'OK'}
2020-06-19 22:37:45,706 -- [test_register.py-->line:52] - DEBUG: 实际结果为：{'code': 2, 'msg': '账号已存在', 'data': None, 'copyright': 'Copyright 柠檬班 © 2017-2020 湖南省零檬信息技术有限公司 All Rights Reserved'}
2020-06-19 22:37:45,706 -- [test_register.py-->line:53] - ERROR: 0 != 2
Traceback (most recent call last):
  File "D:\PychramCode\auto_api_test\testcases\test_register.py", line 46, in test_register
    self.assertEqual(expected["code"], res["code"])
  File "D:\Program Files\Python38\lib\unittest\case.py", line 912, in assertEqual
    assertion_func(first, second, msg=msg)
  File "D:\Program Files\Python38\lib\unittest\case.py", line 905, in _baseAssertEqual
    raise self.failureException(msg)
AssertionError: 0 != 2
2020-06-19 22:37:45,849 -- [test_register.py-->line:50] - ERROR: 用例---成功-不带用户名----执行未通过
2020-06-19 22:37:45,849 -- [test_register.py-->line:51] - DEBUG: 预期结果为：{'code': 0, 'msg': 'OK'}
2020-06-19 22:37:45,849 -- [test_register.py-->line:52] - DEBUG: 实际结果为：{'code': 2, 'msg': '账号已存在', 'data': None, 'copyright': 'Copyright 柠檬班 © 2017-2020 湖南省零檬信息技术有限公司 All Rights Reserved'}
2020-06-19 22:37:45,849 -- [test_register.py-->line:53] - ERROR: 0 != 2
Traceback (most recent call last):
  File "D:\PychramCode\auto_api_test\testcases\test_register.py", line 46, in test_register
    self.assertEqual(expected["code"], res["code"])
  File "D:\Program Files\Python38\lib\unittest\case.py", line 912, in assertEqual
    assertion_func(first, second, msg=msg)
  File "D:\Program Files\Python38\lib\unittest\case.py", line 905, in _baseAssertEqual
    raise self.failureException(msg)
AssertionError: 0 != 2
2020-06-19 22:37:45,975 -- [test_register.py-->line:59] - INFO: 用例---不输入手机号----执行通过
2020-06-19 22:37:46,102 -- [test_register.py-->line:59] - INFO: 用例---手机号长度10位----执行通过
2020-06-19 22:37:46,224 -- [test_register.py-->line:59] - INFO: 用例---手机号长度12位----执行通过
2020-06-19 22:37:46,343 -- [test_register.py-->line:59] - INFO: 用例---手机号含有非法字符----执行通过
2020-06-19 22:37:46,482 -- [test_register.py-->line:59] - INFO: 用例---已注册过的手机号----执行通过
2020-06-19 22:37:46,605 -- [test_register.py-->line:59] - INFO: 用例---密码7位----执行通过
2020-06-19 22:37:46,726 -- [test_register.py-->line:59] - INFO: 用例---密码17位----执行通过
2020-06-19 22:37:46,842 -- [test_register.py-->line:59] - INFO: 用例---不输入密码----执行通过
2020-06-19 22:37:46,960 -- [test_register.py-->line:59] - INFO: 用例---注册名11位----执行通过
2020-06-19 22:37:47,087 -- [test_register.py-->line:59] - INFO: 用例---类型输入非0，1内容----执行通过
2020-06-19 22:37:47,221 -- [test_register.py-->line:50] - ERROR: 用例---不输入类型----执行未通过
2020-06-19 22:37:47,221 -- [test_register.py-->line:51] - DEBUG: 预期结果为：{'code': 0, 'msg': 'OK'}
2020-06-19 22:37:47,221 -- [test_register.py-->line:52] - DEBUG: 实际结果为：{'code': 2, 'msg': '账号已存在', 'data': None, 'copyright': 'Copyright 柠檬班 © 2017-2020 湖南省零檬信息技术有限公司 All Rights Reserved'}
2020-06-19 22:37:47,221 -- [test_register.py-->line:53] - ERROR: 0 != 2
Traceback (most recent call last):
  File "D:\PychramCode\auto_api_test\testcases\test_register.py", line 46, in test_register
    self.assertEqual(expected["code"], res["code"])
  File "D:\Program Files\Python38\lib\unittest\case.py", line 912, in assertEqual
    assertion_func(first, second, msg=msg)
  File "D:\Program Files\Python38\lib\unittest\case.py", line 905, in _baseAssertEqual
    raise self.failureException(msg)
AssertionError: 0 != 2
2020-06-19 22:37:47,276 -- [run_test.py-->line:22] - INFO: ------------------测试案例执行结束--------------------
2020-06-19 22:38:56,086 -- [run_test.py-->line:10] - INFO: --------------------开始执行案例-------------------
2020-06-19 22:38:56,967 -- [test_login.py-->line:59] - INFO: 用例---登录成功----执行通过
2020-06-19 22:38:57,104 -- [test_login.py-->line:59] - INFO: 用例---手机号为空----执行通过
2020-06-19 22:38:57,218 -- [test_login.py-->line:59] - INFO: 用例---密码为空----执行通过
2020-06-19 22:38:57,372 -- [test_login.py-->line:59] - INFO: 用例---手机号未注册----执行通过
2020-06-19 22:38:57,516 -- [test_login.py-->line:59] - INFO: 用例---密码错误----执行通过
2020-06-19 22:38:57,641 -- [test_login.py-->line:59] - INFO: 用例---手机号格式错误----执行通过
2020-06-19 22:38:57,780 -- [test_register.py-->line:50] - ERROR: 用例---注册成功-带注册名----执行未通过
2020-06-19 22:38:57,780 -- [test_register.py-->line:51] - DEBUG: 预期结果为：{'code': 0, 'msg': 'OK'}
2020-06-19 22:38:57,780 -- [test_register.py-->line:52] - DEBUG: 实际结果为：{'code': 2, 'msg': '账号已存在', 'data': None, 'copyright': 'Copyright 柠檬班 © 2017-2020 湖南省零檬信息技术有限公司 All Rights Reserved'}
2020-06-19 22:38:57,780 -- [test_register.py-->line:53] - ERROR: 0 != 2
Traceback (most recent call last):
  File "D:\PychramCode\auto_api_test\testcases\test_register.py", line 46, in test_register
    self.assertEqual(expected["code"], res["code"])
  File "D:\Program Files\Python38\lib\unittest\case.py", line 912, in assertEqual
    assertion_func(first, second, msg=msg)
  File "D:\Program Files\Python38\lib\unittest\case.py", line 905, in _baseAssertEqual
    raise self.failureException(msg)
AssertionError: 0 != 2
2020-06-19 22:38:57,920 -- [test_register.py-->line:50] - ERROR: 用例---成功-不带用户名----执行未通过
2020-06-19 22:38:57,920 -- [test_register.py-->line:51] - DEBUG: 预期结果为：{'code': 0, 'msg': 'OK'}
2020-06-19 22:38:57,920 -- [test_register.py-->line:52] - DEBUG: 实际结果为：{'code': 2, 'msg': '账号已存在', 'data': None, 'copyright': 'Copyright 柠檬班 © 2017-2020 湖南省零檬信息技术有限公司 All Rights Reserved'}
2020-06-19 22:38:57,920 -- [test_register.py-->line:53] - ERROR: 0 != 2
Traceback (most recent call last):
  File "D:\PychramCode\auto_api_test\testcases\test_register.py", line 46, in test_register
    self.assertEqual(expected["code"], res["code"])
  File "D:\Program Files\Python38\lib\unittest\case.py", line 912, in assertEqual
    assertion_func(first, second, msg=msg)
  File "D:\Program Files\Python38\lib\unittest\case.py", line 905, in _baseAssertEqual
    raise self.failureException(msg)
AssertionError: 0 != 2
2020-06-19 22:38:58,047 -- [test_register.py-->line:59] - INFO: 用例---不输入手机号----执行通过
2020-06-19 22:38:58,171 -- [test_register.py-->line:59] - INFO: 用例---手机号长度10位----执行通过
2020-06-19 22:38:58,300 -- [test_register.py-->line:59] - INFO: 用例---手机号长度12位----执行通过
2020-06-19 22:38:58,423 -- [test_register.py-->line:59] - INFO: 用例---手机号含有非法字符----执行通过
2020-06-19 22:38:58,566 -- [test_register.py-->line:59] - INFO: 用例---已注册过的手机号----执行通过
2020-06-19 22:38:58,690 -- [test_register.py-->line:59] - INFO: 用例---密码7位----执行通过
2020-06-19 22:38:58,812 -- [test_register.py-->line:59] - INFO: 用例---密码17位----执行通过
2020-06-19 22:38:58,941 -- [test_register.py-->line:59] - INFO: 用例---不输入密码----执行通过
2020-06-19 22:38:59,062 -- [test_register.py-->line:59] - INFO: 用例---注册名11位----执行通过
2020-06-19 22:38:59,195 -- [test_register.py-->line:59] - INFO: 用例---类型输入非0，1内容----执行通过
2020-06-19 22:38:59,335 -- [test_register.py-->line:50] - ERROR: 用例---不输入类型----执行未通过
2020-06-19 22:38:59,336 -- [test_register.py-->line:51] - DEBUG: 预期结果为：{'code': 0, 'msg': 'OK'}
2020-06-19 22:38:59,336 -- [test_register.py-->line:52] - DEBUG: 实际结果为：{'code': 2, 'msg': '账号已存在', 'data': None, 'copyright': 'Copyright 柠檬班 © 2017-2020 湖南省零檬信息技术有限公司 All Rights Reserved'}
2020-06-19 22:38:59,336 -- [test_register.py-->line:53] - ERROR: 0 != 2
Traceback (most recent call last):
  File "D:\PychramCode\auto_api_test\testcases\test_register.py", line 46, in test_register
    self.assertEqual(expected["code"], res["code"])
  File "D:\Program Files\Python38\lib\unittest\case.py", line 912, in assertEqual
    assertion_func(first, second, msg=msg)
  File "D:\Program Files\Python38\lib\unittest\case.py", line 905, in _baseAssertEqual
    raise self.failureException(msg)
AssertionError: 0 != 2
2020-06-19 22:38:59,393 -- [run_test.py-->line:22] - INFO: ------------------测试案例执行结束--------------------
2020-06-19 22:59:17,750 -- [run_test.py-->line:11] - INFO: --------------------开始执行案例-------------------
2020-06-19 22:59:18,636 -- [test_login.py-->line:59] - INFO: 用例---登录成功----执行通过
2020-06-19 22:59:18,760 -- [test_login.py-->line:59] - INFO: 用例---手机号为空----执行通过
2020-06-19 22:59:18,887 -- [test_login.py-->line:59] - INFO: 用例---密码为空----执行通过
2020-06-19 22:59:19,046 -- [test_login.py-->line:59] - INFO: 用例---手机号未注册----执行通过
2020-06-19 22:59:19,200 -- [test_login.py-->line:59] - INFO: 用例---密码错误----执行通过
2020-06-19 22:59:19,321 -- [test_login.py-->line:59] - INFO: 用例---手机号格式错误----执行通过
2020-06-19 22:59:19,377 -- [run_test.py-->line:23] - INFO: ------------------测试案例执行结束--------------------
2020-06-19 23:02:12,928 -- [run_test.py-->line:11] - INFO: --------------------开始执行案例-------------------
2020-06-19 23:02:13,783 -- [test_login.py-->line:62] - INFO: 用例---登录成功----执行通过
2020-06-19 23:02:13,931 -- [test_login.py-->line:62] - INFO: 用例---手机号为空----执行通过
2020-06-19 23:02:14,052 -- [test_login.py-->line:62] - INFO: 用例---密码为空----执行通过
2020-06-19 23:02:14,212 -- [test_login.py-->line:62] - INFO: 用例---手机号未注册----执行通过
2020-06-19 23:02:14,376 -- [test_login.py-->line:62] - INFO: 用例---密码错误----执行通过
2020-06-19 23:02:14,499 -- [test_login.py-->line:62] - INFO: 用例---手机号格式错误----执行通过
2020-06-19 23:02:14,656 -- [test_register.py-->line:52] - ERROR: 用例---注册成功-带注册名----执行未通过
2020-06-19 23:02:14,656 -- [test_register.py-->line:53] - DEBUG: 预期结果为：{'code': 0, 'msg': 'OK'}
2020-06-19 23:02:14,656 -- [test_register.py-->line:54] - DEBUG: 实际结果为：{'code': 2, 'msg': '账号已存在', 'data': None, 'copyright': 'Copyright 柠檬班 © 2017-2020 湖南省零檬信息技术有限公司 All Rights Reserved'}
2020-06-19 23:02:14,656 -- [test_register.py-->line:55] - ERROR: 0 != 2
Traceback (most recent call last):
  File "D:\PychramCode\auto_api_test\testcases\test_register.py", line 48, in test_register
    self.assertEqual(expected["code"], res["code"])
  File "D:\Program Files\Python38\lib\unittest\case.py", line 912, in assertEqual
    assertion_func(first, second, msg=msg)
  File "D:\Program Files\Python38\lib\unittest\case.py", line 905, in _baseAssertEqual
    raise self.failureException(msg)
AssertionError: 0 != 2
2020-06-19 23:02:14,817 -- [test_register.py-->line:52] - ERROR: 用例---成功-不带用户名----执行未通过
2020-06-19 23:02:14,817 -- [test_register.py-->line:53] - DEBUG: 预期结果为：{'code': 0, 'msg': 'OK'}
2020-06-19 23:02:14,817 -- [test_register.py-->line:54] - DEBUG: 实际结果为：{'code': 2, 'msg': '账号已存在', 'data': None, 'copyright': 'Copyright 柠檬班 © 2017-2020 湖南省零檬信息技术有限公司 All Rights Reserved'}
2020-06-19 23:02:14,817 -- [test_register.py-->line:55] - ERROR: 0 != 2
Traceback (most recent call last):
  File "D:\PychramCode\auto_api_test\testcases\test_register.py", line 48, in test_register
    self.assertEqual(expected["code"], res["code"])
  File "D:\Program Files\Python38\lib\unittest\case.py", line 912, in assertEqual
    assertion_func(first, second, msg=msg)
  File "D:\Program Files\Python38\lib\unittest\case.py", line 905, in _baseAssertEqual
    raise self.failureException(msg)
AssertionError: 0 != 2
2020-06-19 23:02:14,932 -- [test_register.py-->line:61] - INFO: 用例---不输入手机号----执行通过
2020-06-19 23:02:15,054 -- [test_register.py-->line:61] - INFO: 用例---手机号长度10位----执行通过
2020-06-19 23:02:15,177 -- [test_register.py-->line:61] - INFO: 用例---手机号长度12位----执行通过
2020-06-19 23:02:15,295 -- [test_register.py-->line:61] - INFO: 用例---手机号含有非法字符----执行通过
2020-06-19 23:02:15,461 -- [test_register.py-->line:61] - INFO: 用例---已注册过的手机号----执行通过
2020-06-19 23:02:15,580 -- [test_register.py-->line:61] - INFO: 用例---密码7位----执行通过
2020-06-19 23:02:15,703 -- [test_register.py-->line:61] - INFO: 用例---密码17位----执行通过
2020-06-19 23:02:15,819 -- [test_register.py-->line:61] - INFO: 用例---不输入密码----执行通过
2020-06-19 23:02:15,946 -- [test_register.py-->line:61] - INFO: 用例---注册名11位----执行通过
2020-06-19 23:02:16,074 -- [test_register.py-->line:61] - INFO: 用例---类型输入非0，1内容----执行通过
2020-06-19 23:02:16,231 -- [test_register.py-->line:52] - ERROR: 用例---不输入类型----执行未通过
2020-06-19 23:02:16,231 -- [test_register.py-->line:53] - DEBUG: 预期结果为：{'code': 0, 'msg': 'OK'}
2020-06-19 23:02:16,231 -- [test_register.py-->line:54] - DEBUG: 实际结果为：{'code': 2, 'msg': '账号已存在', 'data': None, 'copyright': 'Copyright 柠檬班 © 2017-2020 湖南省零檬信息技术有限公司 All Rights Reserved'}
2020-06-19 23:02:16,231 -- [test_register.py-->line:55] - ERROR: 0 != 2
Traceback (most recent call last):
  File "D:\PychramCode\auto_api_test\testcases\test_register.py", line 48, in test_register
    self.assertEqual(expected["code"], res["code"])
  File "D:\Program Files\Python38\lib\unittest\case.py", line 912, in assertEqual
    assertion_func(first, second, msg=msg)
  File "D:\Program Files\Python38\lib\unittest\case.py", line 905, in _baseAssertEqual
    raise self.failureException(msg)
AssertionError: 0 != 2
2020-06-19 23:02:16,287 -- [run_test.py-->line:23] - INFO: ------------------测试案例执行结束--------------------
2020-06-20 20:17:38,918 -- [run_test.py-->line:11] - INFO: --------------------开始执行案例-------------------
2020-06-20 20:17:42,805 -- [test_login.py-->line:62] - INFO: 用例---登录成功----执行通过
2020-06-20 20:17:42,930 -- [test_login.py-->line:62] - INFO: 用例---手机号为空----执行通过
2020-06-20 20:17:43,047 -- [test_login.py-->line:62] - INFO: 用例---密码为空----执行通过
2020-06-20 20:17:43,194 -- [test_login.py-->line:62] - INFO: 用例---手机号未注册----执行通过
2020-06-20 20:17:43,336 -- [test_login.py-->line:62] - INFO: 用例---密码错误----执行通过
2020-06-20 20:17:43,457 -- [test_login.py-->line:62] - INFO: 用例---手机号格式错误----执行通过
2020-06-20 20:17:43,597 -- [test_register.py-->line:52] - ERROR: 用例---注册成功-带注册名----执行未通过
2020-06-20 20:17:43,597 -- [test_register.py-->line:53] - DEBUG: 预期结果为：{'code': 0, 'msg': 'OK'}
2020-06-20 20:17:43,597 -- [test_register.py-->line:54] - DEBUG: 实际结果为：{'code': 2, 'msg': '账号已存在', 'data': None, 'copyright': 'Copyright 柠檬班 © 2017-2020 湖南省零檬信息技术有限公司 All Rights Reserved'}
2020-06-20 20:17:43,598 -- [test_register.py-->line:55] - ERROR: 0 != 2
Traceback (most recent call last):
  File "D:\PychramCode\auto_api_test\testcases\test_register.py", line 48, in test_register
    self.assertEqual(expected["code"], res["code"])
  File "D:\Program Files\Python38\lib\unittest\case.py", line 912, in assertEqual
    assertion_func(first, second, msg=msg)
  File "D:\Program Files\Python38\lib\unittest\case.py", line 905, in _baseAssertEqual
    raise self.failureException(msg)
AssertionError: 0 != 2
2020-06-20 20:17:43,746 -- [test_register.py-->line:52] - ERROR: 用例---成功-不带用户名----执行未通过
2020-06-20 20:17:43,747 -- [test_register.py-->line:53] - DEBUG: 预期结果为：{'code': 0, 'msg': 'OK'}
2020-06-20 20:17:43,747 -- [test_register.py-->line:54] - DEBUG: 实际结果为：{'code': 2, 'msg': '账号已存在', 'data': None, 'copyright': 'Copyright 柠檬班 © 2017-2020 湖南省零檬信息技术有限公司 All Rights Reserved'}
2020-06-20 20:17:43,747 -- [test_register.py-->line:55] - ERROR: 0 != 2
Traceback (most recent call last):
  File "D:\PychramCode\auto_api_test\testcases\test_register.py", line 48, in test_register
    self.assertEqual(expected["code"], res["code"])
  File "D:\Program Files\Python38\lib\unittest\case.py", line 912, in assertEqual
    assertion_func(first, second, msg=msg)
  File "D:\Program Files\Python38\lib\unittest\case.py", line 905, in _baseAssertEqual
    raise self.failureException(msg)
AssertionError: 0 != 2
2020-06-20 20:17:43,878 -- [test_register.py-->line:61] - INFO: 用例---不输入手机号----执行通过
2020-06-20 20:17:43,999 -- [test_register.py-->line:61] - INFO: 用例---手机号长度10位----执行通过
2020-06-20 20:17:44,113 -- [test_register.py-->line:61] - INFO: 用例---手机号长度12位----执行通过
2020-06-20 20:17:44,238 -- [test_register.py-->line:61] - INFO: 用例---手机号含有非法字符----执行通过
2020-06-20 20:17:44,392 -- [test_register.py-->line:61] - INFO: 用例---已注册过的手机号----执行通过
2020-06-20 20:17:44,505 -- [test_register.py-->line:61] - INFO: 用例---密码7位----执行通过
2020-06-20 20:17:44,619 -- [test_register.py-->line:61] - INFO: 用例---密码17位----执行通过
2020-06-20 20:17:44,738 -- [test_register.py-->line:61] - INFO: 用例---不输入密码----执行通过
2020-06-20 20:17:44,863 -- [test_register.py-->line:61] - INFO: 用例---注册名11位----执行通过
2020-06-20 20:17:44,995 -- [test_register.py-->line:61] - INFO: 用例---类型输入非0，1内容----执行通过
2020-06-20 20:17:45,146 -- [test_register.py-->line:52] - ERROR: 用例---不输入类型----执行未通过
2020-06-20 20:17:45,146 -- [test_register.py-->line:53] - DEBUG: 预期结果为：{'code': 0, 'msg': 'OK'}
2020-06-20 20:17:45,146 -- [test_register.py-->line:54] - DEBUG: 实际结果为：{'code': 2, 'msg': '账号已存在', 'data': None, 'copyright': 'Copyright 柠檬班 © 2017-2020 湖南省零檬信息技术有限公司 All Rights Reserved'}
2020-06-20 20:17:45,146 -- [test_register.py-->line:55] - ERROR: 0 != 2
Traceback (most recent call last):
  File "D:\PychramCode\auto_api_test\testcases\test_register.py", line 48, in test_register
    self.assertEqual(expected["code"], res["code"])
  File "D:\Program Files\Python38\lib\unittest\case.py", line 912, in assertEqual
    assertion_func(first, second, msg=msg)
  File "D:\Program Files\Python38\lib\unittest\case.py", line 905, in _baseAssertEqual
    raise self.failureException(msg)
AssertionError: 0 != 2
2020-06-20 20:17:45,201 -- [run_test.py-->line:23] - INFO: ------------------测试案例执行结束--------------------
2020-06-20 20:18:39,443 -- [run_test.py-->line:11] - INFO: --------------------开始执行案例-------------------
2020-06-20 20:18:40,309 -- [test_login.py-->line:62] - INFO: 用例---登录成功----执行通过
2020-06-20 20:18:40,431 -- [test_login.py-->line:62] - INFO: 用例---手机号为空----执行通过
2020-06-20 20:18:40,542 -- [test_login.py-->line:62] - INFO: 用例---密码为空----执行通过
2020-06-20 20:18:40,667 -- [test_login.py-->line:62] - INFO: 用例---手机号未注册----执行通过
2020-06-20 20:18:40,784 -- [test_login.py-->line:62] - INFO: 用例---密码错误----执行通过
2020-06-20 20:18:40,901 -- [test_login.py-->line:62] - INFO: 用例---手机号格式错误----执行通过
2020-06-20 20:18:41,024 -- [test_register.py-->line:52] - ERROR: 用例---注册成功-带注册名----执行未通过
2020-06-20 20:18:41,024 -- [test_register.py-->line:53] - DEBUG: 预期结果为：{'code': 0, 'msg': 'OK'}
2020-06-20 20:18:41,024 -- [test_register.py-->line:54] - DEBUG: 实际结果为：{'code': 2, 'msg': '账号已存在', 'data': None, 'copyright': 'Copyright 柠檬班 © 2017-2020 湖南省零檬信息技术有限公司 All Rights Reserved'}
2020-06-20 20:18:41,024 -- [test_register.py-->line:55] - ERROR: 0 != 2
Traceback (most recent call last):
  File "D:\PychramCode\auto_api_test\testcases\test_register.py", line 48, in test_register
    self.assertEqual(expected["code"], res["code"])
  File "D:\Program Files\Python38\lib\unittest\case.py", line 912, in assertEqual
    assertion_func(first, second, msg=msg)
  File "D:\Program Files\Python38\lib\unittest\case.py", line 905, in _baseAssertEqual
    raise self.failureException(msg)
AssertionError: 0 != 2
2020-06-20 20:18:41,153 -- [test_register.py-->line:52] - ERROR: 用例---成功-不带用户名----执行未通过
2020-06-20 20:18:41,153 -- [test_register.py-->line:53] - DEBUG: 预期结果为：{'code': 0, 'msg': 'OK'}
2020-06-20 20:18:41,153 -- [test_register.py-->line:54] - DEBUG: 实际结果为：{'code': 2, 'msg': '账号已存在', 'data': None, 'copyright': 'Copyright 柠檬班 © 2017-2020 湖南省零檬信息技术有限公司 All Rights Reserved'}
2020-06-20 20:18:41,153 -- [test_register.py-->line:55] - ERROR: 0 != 2
Traceback (most recent call last):
  File "D:\PychramCode\auto_api_test\testcases\test_register.py", line 48, in test_register
    self.assertEqual(expected["code"], res["code"])
  File "D:\Program Files\Python38\lib\unittest\case.py", line 912, in assertEqual
    assertion_func(first, second, msg=msg)
  File "D:\Program Files\Python38\lib\unittest\case.py", line 905, in _baseAssertEqual
    raise self.failureException(msg)
AssertionError: 0 != 2
2020-06-20 20:18:41,264 -- [test_register.py-->line:61] - INFO: 用例---不输入手机号----执行通过
2020-06-20 20:18:41,386 -- [test_register.py-->line:61] - INFO: 用例---手机号长度10位----执行通过
2020-06-20 20:18:41,503 -- [test_register.py-->line:61] - INFO: 用例---手机号长度12位----执行通过
2020-06-20 20:18:41,617 -- [test_register.py-->line:61] - INFO: 用例---手机号含有非法字符----执行通过
2020-06-20 20:18:41,736 -- [test_register.py-->line:61] - INFO: 用例---已注册过的手机号----执行通过
2020-06-20 20:18:41,851 -- [test_register.py-->line:61] - INFO: 用例---密码7位----执行通过
2020-06-20 20:18:41,967 -- [test_register.py-->line:61] - INFO: 用例---密码17位----执行通过
2020-06-20 20:18:42,099 -- [test_register.py-->line:61] - INFO: 用例---不输入密码----执行通过
2020-06-20 20:18:42,221 -- [test_register.py-->line:61] - INFO: 用例---注册名11位----执行通过
2020-06-20 20:18:42,353 -- [test_register.py-->line:61] - INFO: 用例---类型输入非0，1内容----执行通过
2020-06-20 20:18:42,486 -- [test_register.py-->line:52] - ERROR: 用例---不输入类型----执行未通过
2020-06-20 20:18:42,486 -- [test_register.py-->line:53] - DEBUG: 预期结果为：{'code': 0, 'msg': 'OK'}
2020-06-20 20:18:42,486 -- [test_register.py-->line:54] - DEBUG: 实际结果为：{'code': 2, 'msg': '账号已存在', 'data': None, 'copyright': 'Copyright 柠檬班 © 2017-2020 湖南省零檬信息技术有限公司 All Rights Reserved'}
2020-06-20 20:18:42,486 -- [test_register.py-->line:55] - ERROR: 0 != 2
Traceback (most recent call last):
  File "D:\PychramCode\auto_api_test\testcases\test_register.py", line 48, in test_register
    self.assertEqual(expected["code"], res["code"])
  File "D:\Program Files\Python38\lib\unittest\case.py", line 912, in assertEqual
    assertion_func(first, second, msg=msg)
  File "D:\Program Files\Python38\lib\unittest\case.py", line 905, in _baseAssertEqual
    raise self.failureException(msg)
AssertionError: 0 != 2
2020-06-20 20:18:42,538 -- [run_test.py-->line:24] - INFO: ------------------测试案例执行结束--------------------
2020-06-21 13:57:23,691 -- [run_test.py-->line:11] - INFO: --------------------开始执行案例-------------------
2020-06-21 13:57:25,045 -- [test_login.py-->line:62] - INFO: 用例---登录成功----执行通过
2020-06-21 13:57:25,183 -- [test_login.py-->line:62] - INFO: 用例---手机号为空----执行通过
2020-06-21 13:57:25,331 -- [test_login.py-->line:62] - INFO: 用例---密码为空----执行通过
2020-06-21 13:57:25,506 -- [test_login.py-->line:62] - INFO: 用例---手机号未注册----执行通过
2020-06-21 13:57:25,683 -- [test_login.py-->line:62] - INFO: 用例---密码错误----执行通过
2020-06-21 13:57:25,826 -- [test_login.py-->line:62] - INFO: 用例---手机号格式错误----执行通过
2020-06-21 13:57:25,909 -- [run_test.py-->line:24] - INFO: ------------------测试案例执行结束--------------------
2020-06-21 14:01:49,761 -- [run_test.py-->line:11] - INFO: --------------------开始执行案例-------------------
2020-06-21 14:01:50,816 -- [test_login.py-->line:62] - INFO: 用例---登录成功----执行通过
2020-06-21 14:01:50,967 -- [test_login.py-->line:62] - INFO: 用例---手机号为空----执行通过
2020-06-21 14:01:51,105 -- [test_login.py-->line:62] - INFO: 用例---密码为空----执行通过
2020-06-21 14:01:51,281 -- [test_login.py-->line:62] - INFO: 用例---手机号未注册----执行通过
2020-06-21 14:01:51,453 -- [test_login.py-->line:62] - INFO: 用例---密码错误----执行通过
2020-06-21 14:01:51,588 -- [test_login.py-->line:62] - INFO: 用例---手机号格式错误----执行通过
2020-06-21 14:01:51,728 -- [test_register.py-->line:72] - INFO: 用例---不输入手机号----执行通过
2020-06-21 14:01:51,881 -- [test_register.py-->line:72] - INFO: 用例---手机号长度10位----执行通过
2020-06-21 14:01:52,047 -- [test_register.py-->line:72] - INFO: 用例---手机号长度12位----执行通过
2020-06-21 14:01:52,191 -- [test_register.py-->line:72] - INFO: 用例---手机号含有非法字符----执行通过
2020-06-21 14:01:52,353 -- [test_register.py-->line:72] - INFO: 用例---已注册过的手机号----执行通过
2020-06-21 14:01:52,503 -- [test_register.py-->line:72] - INFO: 用例---密码7位----执行通过
2020-06-21 14:01:52,646 -- [test_register.py-->line:72] - INFO: 用例---密码17位----执行通过
2020-06-21 14:01:52,799 -- [test_register.py-->line:72] - INFO: 用例---不输入密码----执行通过
2020-06-21 14:01:52,937 -- [test_register.py-->line:72] - INFO: 用例---注册名11位----执行通过
2020-06-21 14:01:53,087 -- [test_register.py-->line:72] - INFO: 用例---类型输入非0，1内容----执行通过
2020-06-21 14:01:53,164 -- [run_test.py-->line:24] - INFO: ------------------测试案例执行结束--------------------
2020-06-21 14:04:04,182 -- [test_register.py-->line:72] - INFO: 用例---不输入手机号----执行通过
2020-06-21 14:04:04,331 -- [test_register.py-->line:72] - INFO: 用例---手机号长度10位----执行通过
2020-06-21 14:04:04,471 -- [test_register.py-->line:72] - INFO: 用例---手机号长度12位----执行通过
2020-06-21 14:04:04,612 -- [test_register.py-->line:72] - INFO: 用例---手机号含有非法字符----执行通过
2020-06-21 14:04:04,787 -- [test_register.py-->line:72] - INFO: 用例---已注册过的手机号----执行通过
2020-06-21 14:04:04,940 -- [test_register.py-->line:72] - INFO: 用例---密码7位----执行通过
2020-06-21 14:04:05,081 -- [test_register.py-->line:72] - INFO: 用例---密码17位----执行通过
2020-06-21 14:04:05,220 -- [test_register.py-->line:72] - INFO: 用例---不输入密码----执行通过
2020-06-21 14:04:05,359 -- [test_register.py-->line:72] - INFO: 用例---注册名11位----执行通过
2020-06-21 14:04:05,536 -- [test_register.py-->line:72] - INFO: 用例---类型输入非0，1内容----执行通过
2020-06-21 14:06:36,915 -- [run_test.py-->line:11] - INFO: --------------------开始执行案例-------------------
2020-06-21 14:06:37,992 -- [test_login.py-->line:62] - INFO: 用例---登录成功----执行通过
2020-06-21 14:06:38,133 -- [test_login.py-->line:62] - INFO: 用例---手机号为空----执行通过
2020-06-21 14:06:38,267 -- [test_login.py-->line:62] - INFO: 用例---密码为空----执行通过
2020-06-21 14:06:38,432 -- [test_login.py-->line:62] - INFO: 用例---手机号未注册----执行通过
2020-06-21 14:06:38,607 -- [test_login.py-->line:62] - INFO: 用例---密码错误----执行通过
2020-06-21 14:06:38,753 -- [test_login.py-->line:62] - INFO: 用例---手机号格式错误----执行通过
2020-06-21 14:07:15,705 -- [run_test.py-->line:11] - INFO: --------------------开始执行案例-------------------
2020-06-21 14:07:16,727 -- [test_login.py-->line:62] - INFO: 用例---登录成功----执行通过
2020-06-21 14:07:16,870 -- [test_login.py-->line:62] - INFO: 用例---手机号为空----执行通过
2020-06-21 14:07:17,005 -- [test_login.py-->line:62] - INFO: 用例---密码为空----执行通过
2020-06-21 14:07:17,143 -- [test_login.py-->line:62] - INFO: 用例---手机号未注册----执行通过
2020-06-21 14:07:17,287 -- [test_login.py-->line:62] - INFO: 用例---密码错误----执行通过
2020-06-21 14:07:17,432 -- [test_login.py-->line:62] - INFO: 用例---手机号格式错误----执行通过
2020-06-21 14:14:32,027 -- [run_test.py-->line:11] - INFO: --------------------开始执行案例-------------------
2020-06-21 14:14:36,128 -- [test_login.py-->line:62] - INFO: 用例---登录成功----执行通过
2020-06-21 14:14:36,371 -- [test_login.py-->line:62] - INFO: 用例---手机号为空----执行通过
2020-06-21 14:14:36,484 -- [test_login.py-->line:62] - INFO: 用例---密码为空----执行通过
2020-06-21 14:14:36,621 -- [test_login.py-->line:62] - INFO: 用例---手机号未注册----执行通过
2020-06-21 14:14:36,767 -- [test_login.py-->line:62] - INFO: 用例---密码错误----执行通过
2020-06-21 14:14:36,875 -- [test_login.py-->line:62] - INFO: 用例---手机号格式错误----执行通过
2020-06-21 14:14:46,119 -- [run_test.py-->line:11] - INFO: --------------------开始执行案例-------------------
2020-06-21 14:14:47,104 -- [test_login.py-->line:62] - INFO: 用例---登录成功----执行通过
2020-06-21 14:14:47,247 -- [test_login.py-->line:62] - INFO: 用例---手机号为空----执行通过
2020-06-21 14:14:47,389 -- [test_login.py-->line:62] - INFO: 用例---密码为空----执行通过
2020-06-21 14:14:47,539 -- [test_login.py-->line:62] - INFO: 用例---手机号未注册----执行通过
2020-06-21 14:14:47,672 -- [test_login.py-->line:62] - INFO: 用例---密码错误----执行通过
2020-06-21 14:14:47,819 -- [test_login.py-->line:62] - INFO: 用例---手机号格式错误----执行通过
2020-06-21 14:14:59,308 -- [run_test.py-->line:11] - INFO: --------------------开始执行案例-------------------
2020-06-21 14:15:00,594 -- [test_login.py-->line:62] - INFO: 用例---登录成功----执行通过
2020-06-21 14:15:00,836 -- [test_login.py-->line:62] - INFO: 用例---手机号为空----执行通过
2020-06-21 14:15:01,069 -- [test_login.py-->line:62] - INFO: 用例---密码为空----执行通过
2020-06-21 14:15:01,323 -- [test_login.py-->line:62] - INFO: 用例---手机号未注册----执行通过
2020-06-21 14:15:01,586 -- [test_login.py-->line:62] - INFO: 用例---密码错误----执行通过
2020-06-21 14:15:01,809 -- [test_login.py-->line:62] - INFO: 用例---手机号格式错误----执行通过
2020-06-21 14:23:00,169 -- [test_register.py-->line:72] - INFO: 用例---注册成功-带注册名----执行通过
2020-06-21 14:23:00,501 -- [test_register.py-->line:72] - INFO: 用例---成功-不带用户名----执行通过
2020-06-21 14:23:00,600 -- [test_register.py-->line:72] - INFO: 用例---不输入手机号----执行通过
2020-06-21 14:23:00,701 -- [test_register.py-->line:72] - INFO: 用例---手机号长度10位----执行通过
2020-06-21 14:23:00,804 -- [test_register.py-->line:72] - INFO: 用例---手机号长度12位----执行通过
2020-06-21 14:23:00,907 -- [test_register.py-->line:72] - INFO: 用例---手机号含有非法字符----执行通过
2020-06-21 14:23:01,038 -- [test_register.py-->line:72] - INFO: 用例---已注册过的手机号----执行通过
2020-06-21 14:23:01,145 -- [test_register.py-->line:72] - INFO: 用例---密码7位----执行通过
2020-06-21 14:23:01,255 -- [test_register.py-->line:72] - INFO: 用例---密码17位----执行通过
2020-06-21 14:23:01,359 -- [test_register.py-->line:72] - INFO: 用例---不输入密码----执行通过
2020-06-21 14:23:01,475 -- [test_register.py-->line:72] - INFO: 用例---注册名11位----执行通过
2020-06-21 14:23:01,582 -- [test_register.py-->line:72] - INFO: 用例---类型输入非0，1内容----执行通过
2020-06-21 14:23:01,931 -- [test_register.py-->line:72] - INFO: 用例---不输入类型----执行通过
2020-06-21 14:23:12,192 -- [run_test.py-->line:11] - INFO: --------------------开始执行案例-------------------
2020-06-21 14:23:16,212 -- [test_login.py-->line:62] - INFO: 用例---登录成功----执行通过
2020-06-21 14:23:16,315 -- [test_login.py-->line:62] - INFO: 用例---手机号为空----执行通过
2020-06-21 14:23:16,418 -- [test_login.py-->line:62] - INFO: 用例---密码为空----执行通过
2020-06-21 14:23:16,558 -- [test_login.py-->line:62] - INFO: 用例---手机号未注册----执行通过
2020-06-21 14:23:16,692 -- [test_login.py-->line:62] - INFO: 用例---密码错误----执行通过
2020-06-21 14:23:16,798 -- [test_login.py-->line:62] - INFO: 用例---手机号格式错误----执行通过
2020-06-21 14:23:17,144 -- [test_register.py-->line:72] - INFO: 用例---注册成功-带注册名----执行通过
2020-06-21 14:23:17,491 -- [test_register.py-->line:72] - INFO: 用例---成功-不带用户名----执行通过
2020-06-21 14:23:17,598 -- [test_register.py-->line:72] - INFO: 用例---不输入手机号----执行通过
2020-06-21 14:23:17,711 -- [test_register.py-->line:72] - INFO: 用例---手机号长度10位----执行通过
2020-06-21 14:23:17,827 -- [test_register.py-->line:72] - INFO: 用例---手机号长度12位----执行通过
2020-06-21 14:23:17,925 -- [test_register.py-->line:72] - INFO: 用例---手机号含有非法字符----执行通过
2020-06-21 14:23:18,054 -- [test_register.py-->line:72] - INFO: 用例---已注册过的手机号----执行通过
2020-06-21 14:23:18,158 -- [test_register.py-->line:72] - INFO: 用例---密码7位----执行通过
2020-06-21 14:23:18,266 -- [test_register.py-->line:72] - INFO: 用例---密码17位----执行通过
2020-06-21 14:23:18,370 -- [test_register.py-->line:72] - INFO: 用例---不输入密码----执行通过
2020-06-21 14:23:18,471 -- [test_register.py-->line:72] - INFO: 用例---注册名11位----执行通过
2020-06-21 14:23:18,572 -- [test_register.py-->line:72] - INFO: 用例---类型输入非0，1内容----执行通过
2020-06-21 14:23:18,921 -- [test_register.py-->line:72] - INFO: 用例---不输入类型----执行通过
2020-06-21 14:23:18,963 -- [run_test.py-->line:24] - INFO: ------------------测试案例执行结束--------------------
2020-06-21 14:23:29,985 -- [run_test.py-->line:11] - INFO: --------------------开始执行案例-------------------
2020-06-21 14:23:34,014 -- [test_login.py-->line:62] - INFO: 用例---登录成功----执行通过
2020-06-21 14:23:34,153 -- [test_login.py-->line:62] - INFO: 用例---手机号为空----执行通过
2020-06-21 14:23:34,288 -- [test_login.py-->line:62] - INFO: 用例---密码为空----执行通过
2020-06-21 14:23:34,463 -- [test_login.py-->line:62] - INFO: 用例---手机号未注册----执行通过
2020-06-21 14:23:34,646 -- [test_login.py-->line:62] - INFO: 用例---密码错误----执行通过
2020-06-21 14:23:34,787 -- [test_login.py-->line:62] - INFO: 用例---手机号格式错误----执行通过
2020-06-21 14:23:35,136 -- [test_register.py-->line:72] - INFO: 用例---注册成功-带注册名----执行通过
2020-06-21 14:23:35,519 -- [test_register.py-->line:72] - INFO: 用例---成功-不带用户名----执行通过
2020-06-21 14:23:35,657 -- [test_register.py-->line:72] - INFO: 用例---不输入手机号----执行通过
2020-06-21 14:23:35,811 -- [test_register.py-->line:72] - INFO: 用例---手机号长度10位----执行通过
2020-06-21 14:23:35,950 -- [test_register.py-->line:72] - INFO: 用例---手机号长度12位----执行通过
2020-06-21 14:23:36,093 -- [test_register.py-->line:72] - INFO: 用例---手机号含有非法字符----执行通过
2020-06-21 14:23:36,264 -- [test_register.py-->line:72] - INFO: 用例---已注册过的手机号----执行通过
2020-06-21 14:23:36,402 -- [test_register.py-->line:72] - INFO: 用例---密码7位----执行通过
2020-06-21 14:23:36,546 -- [test_register.py-->line:72] - INFO: 用例---密码17位----执行通过
2020-06-21 14:23:36,683 -- [test_register.py-->line:72] - INFO: 用例---不输入密码----执行通过
2020-06-21 14:23:36,824 -- [test_register.py-->line:72] - INFO: 用例---注册名11位----执行通过
2020-06-21 14:23:36,963 -- [test_register.py-->line:72] - INFO: 用例---类型输入非0，1内容----执行通过
2020-06-21 14:23:37,347 -- [test_register.py-->line:72] - INFO: 用例---不输入类型----执行通过
2020-06-21 14:23:37,424 -- [run_test.py-->line:24] - INFO: ------------------测试案例执行结束--------------------
2020-06-21 20:34:36,597 -- [test_recharge.py-->line:92] - DEBUG: ----用例会员id为空执行完成-------
2020-06-21 20:34:36,598 -- [test_recharge.py-->line:93] - ERROR:  :: 1 != [1004]
Traceback (most recent call last):
  File "C:\Program Files\JetBrains\PyCharm Community Edition 2019.3.4\plugins\python-ce\helpers\pycharm\teamcity\diff_tools.py", line 32, in _patched_equals
    old(self, first, second, msg)
  File "D:\Program Files\Python38\lib\unittest\case.py", line 912, in assertEqual
    assertion_func(first, second, msg=msg)
  File "D:\Program Files\Python38\lib\unittest\case.py", line 905, in _baseAssertEqual
    raise self.failureException(msg)
AssertionError: 1 != [1004]

During handling of the above exception, another exception occurred:

Traceback (most recent call last):
  File "D:\PychramCode\auto_api_test\testcases\test_recharge.py", line 83, in test_recharge
    self.assertEqual(expected["code"], jsonpath(res, "$..code"))
  File "C:\Program Files\JetBrains\PyCharm Community Edition 2019.3.4\plugins\python-ce\helpers\pycharm\teamcity\diff_tools.py", line 38, in _patched_equals
    raise error
teamcity.diff_tools.EqualsAssertionError:  :: 1 != [1004]
2020-06-21 20:34:36,761 -- [test_recharge.py-->line:92] - DEBUG: ----用例id不是当前登录的用户执行完成-------
2020-06-21 20:34:36,761 -- [test_recharge.py-->line:93] - ERROR:  :: 1007 != [1004]
Traceback (most recent call last):
  File "C:\Program Files\JetBrains\PyCharm Community Edition 2019.3.4\plugins\python-ce\helpers\pycharm\teamcity\diff_tools.py", line 32, in _patched_equals
    old(self, first, second, msg)
  File "D:\Program Files\Python38\lib\unittest\case.py", line 912, in assertEqual
    assertion_func(first, second, msg=msg)
  File "D:\Program Files\Python38\lib\unittest\case.py", line 905, in _baseAssertEqual
    raise self.failureException(msg)
AssertionError: 1007 != [1004]

During handling of the above exception, another exception occurred:

Traceback (most recent call last):
  File "D:\PychramCode\auto_api_test\testcases\test_recharge.py", line 83, in test_recharge
    self.assertEqual(expected["code"], jsonpath(res, "$..code"))
  File "C:\Program Files\JetBrains\PyCharm Community Edition 2019.3.4\plugins\python-ce\helpers\pycharm\teamcity\diff_tools.py", line 38, in _patched_equals
    raise error
teamcity.diff_tools.EqualsAssertionError:  :: 1007 != [1004]
2020-06-21 20:34:36,912 -- [test_recharge.py-->line:92] - DEBUG: ----用例会员id为字符串执行完成-------
2020-06-21 20:34:36,913 -- [test_recharge.py-->line:93] - ERROR:  :: 2 != [1004]
Traceback (most recent call last):
  File "C:\Program Files\JetBrains\PyCharm Community Edition 2019.3.4\plugins\python-ce\helpers\pycharm\teamcity\diff_tools.py", line 32, in _patched_equals
    old(self, first, second, msg)
  File "D:\Program Files\Python38\lib\unittest\case.py", line 912, in assertEqual
    assertion_func(first, second, msg=msg)
  File "D:\Program Files\Python38\lib\unittest\case.py", line 905, in _baseAssertEqual
    raise self.failureException(msg)
AssertionError: 2 != [1004]

During handling of the above exception, another exception occurred:

Traceback (most recent call last):
  File "D:\PychramCode\auto_api_test\testcases\test_recharge.py", line 83, in test_recharge
    self.assertEqual(expected["code"], jsonpath(res, "$..code"))
  File "C:\Program Files\JetBrains\PyCharm Community Edition 2019.3.4\plugins\python-ce\helpers\pycharm\teamcity\diff_tools.py", line 38, in _patched_equals
    raise error
teamcity.diff_tools.EqualsAssertionError:  :: 2 != [1004]
2020-06-21 20:34:37,057 -- [test_recharge.py-->line:92] - DEBUG: ----用例会员id为小数执行完成-------
2020-06-21 20:34:37,057 -- [test_recharge.py-->line:93] - ERROR:  :: 2 != [1004]
Traceback (most recent call last):
  File "C:\Program Files\JetBrains\PyCharm Community Edition 2019.3.4\plugins\python-ce\helpers\pycharm\teamcity\diff_tools.py", line 32, in _patched_equals
    old(self, first, second, msg)
  File "D:\Program Files\Python38\lib\unittest\case.py", line 912, in assertEqual
    assertion_func(first, second, msg=msg)
  File "D:\Program Files\Python38\lib\unittest\case.py", line 905, in _baseAssertEqual
    raise self.failureException(msg)
AssertionError: 2 != [1004]

During handling of the above exception, another exception occurred:

Traceback (most recent call last):
  File "D:\PychramCode\auto_api_test\testcases\test_recharge.py", line 83, in test_recharge
    self.assertEqual(expected["code"], jsonpath(res, "$..code"))
  File "C:\Program Files\JetBrains\PyCharm Community Edition 2019.3.4\plugins\python-ce\helpers\pycharm\teamcity\diff_tools.py", line 38, in _patched_equals
    raise error
teamcity.diff_tools.EqualsAssertionError:  :: 2 != [1004]
2020-06-21 20:34:37,199 -- [test_recharge.py-->line:92] - DEBUG: ----用例充值金额为0执行完成-------
2020-06-21 20:34:37,199 -- [test_recharge.py-->line:93] - ERROR:  :: 2 != [1004]
Traceback (most recent call last):
  File "C:\Program Files\JetBrains\PyCharm Community Edition 2019.3.4\plugins\python-ce\helpers\pycharm\teamcity\diff_tools.py", line 32, in _patched_equals
    old(self, first, second, msg)
  File "D:\Program Files\Python38\lib\unittest\case.py", line 912, in assertEqual
    assertion_func(first, second, msg=msg)
  File "D:\Program Files\Python38\lib\unittest\case.py", line 905, in _baseAssertEqual
    raise self.failureException(msg)
AssertionError: 2 != [1004]

During handling of the above exception, another exception occurred:

Traceback (most recent call last):
  File "D:\PychramCode\auto_api_test\testcases\test_recharge.py", line 83, in test_recharge
    self.assertEqual(expected["code"], jsonpath(res, "$..code"))
  File "C:\Program Files\JetBrains\PyCharm Community Edition 2019.3.4\plugins\python-ce\helpers\pycharm\teamcity\diff_tools.py", line 38, in _patched_equals
    raise error
teamcity.diff_tools.EqualsAssertionError:  :: 2 != [1004]
2020-06-21 20:34:37,354 -- [test_recharge.py-->line:92] - DEBUG: ----用例充值金额为负数执行完成-------
2020-06-21 20:34:37,355 -- [test_recharge.py-->line:93] - ERROR:  :: 2 != [1004]
Traceback (most recent call last):
  File "C:\Program Files\JetBrains\PyCharm Community Edition 2019.3.4\plugins\python-ce\helpers\pycharm\teamcity\diff_tools.py", line 32, in _patched_equals
    old(self, first, second, msg)
  File "D:\Program Files\Python38\lib\unittest\case.py", line 912, in assertEqual
    assertion_func(first, second, msg=msg)
  File "D:\Program Files\Python38\lib\unittest\case.py", line 905, in _baseAssertEqual
    raise self.failureException(msg)
AssertionError: 2 != [1004]

During handling of the above exception, another exception occurred:

Traceback (most recent call last):
  File "D:\PychramCode\auto_api_test\testcases\test_recharge.py", line 83, in test_recharge
    self.assertEqual(expected["code"], jsonpath(res, "$..code"))
  File "C:\Program Files\JetBrains\PyCharm Community Edition 2019.3.4\plugins\python-ce\helpers\pycharm\teamcity\diff_tools.py", line 38, in _patched_equals
    raise error
teamcity.diff_tools.EqualsAssertionError:  :: 2 != [1004]
2020-06-21 20:34:37,508 -- [test_recharge.py-->line:92] - DEBUG: ----用例充值金额为空执行完成-------
2020-06-21 20:34:37,508 -- [test_recharge.py-->line:93] - ERROR:  :: 1 != [1004]
Traceback (most recent call last):
  File "C:\Program Files\JetBrains\PyCharm Community Edition 2019.3.4\plugins\python-ce\helpers\pycharm\teamcity\diff_tools.py", line 32, in _patched_equals
    old(self, first, second, msg)
  File "D:\Program Files\Python38\lib\unittest\case.py", line 912, in assertEqual
    assertion_func(first, second, msg=msg)
  File "D:\Program Files\Python38\lib\unittest\case.py", line 905, in _baseAssertEqual
    raise self.failureException(msg)
AssertionError: 1 != [1004]

During handling of the above exception, another exception occurred:

Traceback (most recent call last):
  File "D:\PychramCode\auto_api_test\testcases\test_recharge.py", line 83, in test_recharge
    self.assertEqual(expected["code"], jsonpath(res, "$..code"))
  File "C:\Program Files\JetBrains\PyCharm Community Edition 2019.3.4\plugins\python-ce\helpers\pycharm\teamcity\diff_tools.py", line 38, in _patched_equals
    raise error
teamcity.diff_tools.EqualsAssertionError:  :: 1 != [1004]
2020-06-21 20:34:37,654 -- [test_recharge.py-->line:92] - DEBUG: ----用例充值金额-3位小数执行完成-------
2020-06-21 20:34:37,655 -- [test_recharge.py-->line:93] - ERROR:  :: 2 != [1004]
Traceback (most recent call last):
  File "C:\Program Files\JetBrains\PyCharm Community Edition 2019.3.4\plugins\python-ce\helpers\pycharm\teamcity\diff_tools.py", line 32, in _patched_equals
    old(self, first, second, msg)
  File "D:\Program Files\Python38\lib\unittest\case.py", line 912, in assertEqual
    assertion_func(first, second, msg=msg)
  File "D:\Program Files\Python38\lib\unittest\case.py", line 905, in _baseAssertEqual
    raise self.failureException(msg)
AssertionError: 2 != [1004]

During handling of the above exception, another exception occurred:

Traceback (most recent call last):
  File "D:\PychramCode\auto_api_test\testcases\test_recharge.py", line 83, in test_recharge
    self.assertEqual(expected["code"], jsonpath(res, "$..code"))
  File "C:\Program Files\JetBrains\PyCharm Community Edition 2019.3.4\plugins\python-ce\helpers\pycharm\teamcity\diff_tools.py", line 38, in _patched_equals
    raise error
teamcity.diff_tools.EqualsAssertionError:  :: 2 != [1004]
2020-06-21 20:34:37,809 -- [test_recharge.py-->line:92] - DEBUG: ----用例充值金额-大于50万执行完成-------
2020-06-21 20:34:37,809 -- [test_recharge.py-->line:93] - ERROR:  :: 2 != [1004]
Traceback (most recent call last):
  File "C:\Program Files\JetBrains\PyCharm Community Edition 2019.3.4\plugins\python-ce\helpers\pycharm\teamcity\diff_tools.py", line 32, in _patched_equals
    old(self, first, second, msg)
  File "D:\Program Files\Python38\lib\unittest\case.py", line 912, in assertEqual
    assertion_func(first, second, msg=msg)
  File "D:\Program Files\Python38\lib\unittest\case.py", line 905, in _baseAssertEqual
    raise self.failureException(msg)
AssertionError: 2 != [1004]

During handling of the above exception, another exception occurred:

Traceback (most recent call last):
  File "D:\PychramCode\auto_api_test\testcases\test_recharge.py", line 83, in test_recharge
    self.assertEqual(expected["code"], jsonpath(res, "$..code"))
  File "C:\Program Files\JetBrains\PyCharm Community Edition 2019.3.4\plugins\python-ce\helpers\pycharm\teamcity\diff_tools.py", line 38, in _patched_equals
    raise error
teamcity.diff_tools.EqualsAssertionError:  :: 2 != [1004]
2020-06-21 20:34:37,972 -- [test_recharge.py-->line:92] - DEBUG: ----用例充值金额-非数字执行完成-------
2020-06-21 20:34:37,972 -- [test_recharge.py-->line:93] - ERROR:  :: 2 != [1004]
Traceback (most recent call last):
  File "C:\Program Files\JetBrains\PyCharm Community Edition 2019.3.4\plugins\python-ce\helpers\pycharm\teamcity\diff_tools.py", line 32, in _patched_equals
    old(self, first, second, msg)
  File "D:\Program Files\Python38\lib\unittest\case.py", line 912, in assertEqual
    assertion_func(first, second, msg=msg)
  File "D:\Program Files\Python38\lib\unittest\case.py", line 905, in _baseAssertEqual
    raise self.failureException(msg)
AssertionError: 2 != [1004]

During handling of the above exception, another exception occurred:

Traceback (most recent call last):
  File "D:\PychramCode\auto_api_test\testcases\test_recharge.py", line 83, in test_recharge
    self.assertEqual(expected["code"], jsonpath(res, "$..code"))
  File "C:\Program Files\JetBrains\PyCharm Community Edition 2019.3.4\plugins\python-ce\helpers\pycharm\teamcity\diff_tools.py", line 38, in _patched_equals
    raise error
teamcity.diff_tools.EqualsAssertionError:  :: 2 != [1004]
2020-06-21 20:36:22,511 -- [test_recharge.py-->line:92] - DEBUG: ----用例充值成功-整数执行完成-------
2020-06-21 20:36:22,512 -- [test_recharge.py-->line:93] - ERROR:  :: 0 != [1004]
Traceback (most recent call last):
  File "C:\Program Files\JetBrains\PyCharm Community Edition 2019.3.4\plugins\python-ce\helpers\pycharm\teamcity\diff_tools.py", line 32, in _patched_equals
    old(self, first, second, msg)
  File "D:\Program Files\Python38\lib\unittest\case.py", line 912, in assertEqual
    assertion_func(first, second, msg=msg)
  File "D:\Program Files\Python38\lib\unittest\case.py", line 905, in _baseAssertEqual
    raise self.failureException(msg)
AssertionError: 0 != [1004]

During handling of the above exception, another exception occurred:

Traceback (most recent call last):
  File "D:\PychramCode\auto_api_test\testcases\test_recharge.py", line 83, in test_recharge
    self.assertEqual(expected["code"], jsonpath(res, "$..code"))
  File "C:\Program Files\JetBrains\PyCharm Community Edition 2019.3.4\plugins\python-ce\helpers\pycharm\teamcity\diff_tools.py", line 38, in _patched_equals
    raise error
teamcity.diff_tools.EqualsAssertionError:  :: 0 != [1004]
2020-06-21 20:36:22,804 -- [test_recharge.py-->line:92] - DEBUG: ----用例充值成功-1位小数执行完成-------
2020-06-21 20:36:22,804 -- [test_recharge.py-->line:93] - ERROR:  :: 0 != [1004]
Traceback (most recent call last):
  File "C:\Program Files\JetBrains\PyCharm Community Edition 2019.3.4\plugins\python-ce\helpers\pycharm\teamcity\diff_tools.py", line 32, in _patched_equals
    old(self, first, second, msg)
  File "D:\Program Files\Python38\lib\unittest\case.py", line 912, in assertEqual
    assertion_func(first, second, msg=msg)
  File "D:\Program Files\Python38\lib\unittest\case.py", line 905, in _baseAssertEqual
    raise self.failureException(msg)
AssertionError: 0 != [1004]

During handling of the above exception, another exception occurred:

Traceback (most recent call last):
  File "D:\PychramCode\auto_api_test\testcases\test_recharge.py", line 83, in test_recharge
    self.assertEqual(expected["code"], jsonpath(res, "$..code"))
  File "C:\Program Files\JetBrains\PyCharm Community Edition 2019.3.4\plugins\python-ce\helpers\pycharm\teamcity\diff_tools.py", line 38, in _patched_equals
    raise error
teamcity.diff_tools.EqualsAssertionError:  :: 0 != [1004]
2020-06-21 20:36:23,095 -- [test_recharge.py-->line:92] - DEBUG: ----用例充值成功-2位小数执行完成-------
2020-06-21 20:36:23,095 -- [test_recharge.py-->line:93] - ERROR:  :: 0 != [1004]
Traceback (most recent call last):
  File "C:\Program Files\JetBrains\PyCharm Community Edition 2019.3.4\plugins\python-ce\helpers\pycharm\teamcity\diff_tools.py", line 32, in _patched_equals
    old(self, first, second, msg)
  File "D:\Program Files\Python38\lib\unittest\case.py", line 912, in assertEqual
    assertion_func(first, second, msg=msg)
  File "D:\Program Files\Python38\lib\unittest\case.py", line 905, in _baseAssertEqual
    raise self.failureException(msg)
AssertionError: 0 != [1004]

During handling of the above exception, another exception occurred:

Traceback (most recent call last):
  File "D:\PychramCode\auto_api_test\testcases\test_recharge.py", line 83, in test_recharge
    self.assertEqual(expected["code"], jsonpath(res, "$..code"))
  File "C:\Program Files\JetBrains\PyCharm Community Edition 2019.3.4\plugins\python-ce\helpers\pycharm\teamcity\diff_tools.py", line 38, in _patched_equals
    raise error
teamcity.diff_tools.EqualsAssertionError:  :: 0 != [1004]
2020-06-21 20:36:23,380 -- [test_recharge.py-->line:92] - DEBUG: ----用例充值成功-50万执行完成-------
2020-06-21 20:36:23,381 -- [test_recharge.py-->line:93] - ERROR:  :: 0 != [1004]
Traceback (most recent call last):
  File "C:\Program Files\JetBrains\PyCharm Community Edition 2019.3.4\plugins\python-ce\helpers\pycharm\teamcity\diff_tools.py", line 32, in _patched_equals
    old(self, first, second, msg)
  File "D:\Program Files\Python38\lib\unittest\case.py", line 912, in assertEqual
    assertion_func(first, second, msg=msg)
  File "D:\Program Files\Python38\lib\unittest\case.py", line 905, in _baseAssertEqual
    raise self.failureException(msg)
AssertionError: 0 != [1004]

During handling of the above exception, another exception occurred:

Traceback (most recent call last):
  File "D:\PychramCode\auto_api_test\testcases\test_recharge.py", line 83, in test_recharge
    self.assertEqual(expected["code"], jsonpath(res, "$..code"))
  File "C:\Program Files\JetBrains\PyCharm Community Edition 2019.3.4\plugins\python-ce\helpers\pycharm\teamcity\diff_tools.py", line 38, in _patched_equals
    raise error
teamcity.diff_tools.EqualsAssertionError:  :: 0 != [1004]
2020-06-21 20:36:23,540 -- [test_recharge.py-->line:92] - DEBUG: ----用例会员id为空执行完成-------
2020-06-21 20:36:23,540 -- [test_recharge.py-->line:93] - ERROR:  :: 1 != [1004]
Traceback (most recent call last):
  File "C:\Program Files\JetBrains\PyCharm Community Edition 2019.3.4\plugins\python-ce\helpers\pycharm\teamcity\diff_tools.py", line 32, in _patched_equals
    old(self, first, second, msg)
  File "D:\Program Files\Python38\lib\unittest\case.py", line 912, in assertEqual
    assertion_func(first, second, msg=msg)
  File "D:\Program Files\Python38\lib\unittest\case.py", line 905, in _baseAssertEqual
    raise self.failureException(msg)
AssertionError: 1 != [1004]

During handling of the above exception, another exception occurred:

Traceback (most recent call last):
  File "D:\PychramCode\auto_api_test\testcases\test_recharge.py", line 83, in test_recharge
    self.assertEqual(expected["code"], jsonpath(res, "$..code"))
  File "C:\Program Files\JetBrains\PyCharm Community Edition 2019.3.4\plugins\python-ce\helpers\pycharm\teamcity\diff_tools.py", line 38, in _patched_equals
    raise error
teamcity.diff_tools.EqualsAssertionError:  :: 1 != [1004]
2020-06-21 20:36:23,714 -- [test_recharge.py-->line:92] - DEBUG: ----用例id不是当前登录的用户执行完成-------
2020-06-21 20:36:23,714 -- [test_recharge.py-->line:93] - ERROR:  :: 1007 != [1004]
Traceback (most recent call last):
  File "C:\Program Files\JetBrains\PyCharm Community Edition 2019.3.4\plugins\python-ce\helpers\pycharm\teamcity\diff_tools.py", line 32, in _patched_equals
    old(self, first, second, msg)
  File "D:\Program Files\Python38\lib\unittest\case.py", line 912, in assertEqual
    assertion_func(first, second, msg=msg)
  File "D:\Program Files\Python38\lib\unittest\case.py", line 905, in _baseAssertEqual
    raise self.failureException(msg)
AssertionError: 1007 != [1004]

During handling of the above exception, another exception occurred:

Traceback (most recent call last):
  File "D:\PychramCode\auto_api_test\testcases\test_recharge.py", line 83, in test_recharge
    self.assertEqual(expected["code"], jsonpath(res, "$..code"))
  File "C:\Program Files\JetBrains\PyCharm Community Edition 2019.3.4\plugins\python-ce\helpers\pycharm\teamcity\diff_tools.py", line 38, in _patched_equals
    raise error
teamcity.diff_tools.EqualsAssertionError:  :: 1007 != [1004]
2020-06-21 20:36:23,875 -- [test_recharge.py-->line:92] - DEBUG: ----用例会员id为字符串执行完成-------
2020-06-21 20:36:23,875 -- [test_recharge.py-->line:93] - ERROR:  :: 2 != [1004]
Traceback (most recent call last):
  File "C:\Program Files\JetBrains\PyCharm Community Edition 2019.3.4\plugins\python-ce\helpers\pycharm\teamcity\diff_tools.py", line 32, in _patched_equals
    old(self, first, second, msg)
  File "D:\Program Files\Python38\lib\unittest\case.py", line 912, in assertEqual
    assertion_func(first, second, msg=msg)
  File "D:\Program Files\Python38\lib\unittest\case.py", line 905, in _baseAssertEqual
    raise self.failureException(msg)
AssertionError: 2 != [1004]

During handling of the above exception, another exception occurred:

Traceback (most recent call last):
  File "D:\PychramCode\auto_api_test\testcases\test_recharge.py", line 83, in test_recharge
    self.assertEqual(expected["code"], jsonpath(res, "$..code"))
  File "C:\Program Files\JetBrains\PyCharm Community Edition 2019.3.4\plugins\python-ce\helpers\pycharm\teamcity\diff_tools.py", line 38, in _patched_equals
    raise error
teamcity.diff_tools.EqualsAssertionError:  :: 2 != [1004]
2020-06-21 20:36:24,039 -- [test_recharge.py-->line:92] - DEBUG: ----用例会员id为小数执行完成-------
2020-06-21 20:36:24,039 -- [test_recharge.py-->line:93] - ERROR:  :: 2 != [1004]
Traceback (most recent call last):
  File "C:\Program Files\JetBrains\PyCharm Community Edition 2019.3.4\plugins\python-ce\helpers\pycharm\teamcity\diff_tools.py", line 32, in _patched_equals
    old(self, first, second, msg)
  File "D:\Program Files\Python38\lib\unittest\case.py", line 912, in assertEqual
    assertion_func(first, second, msg=msg)
  File "D:\Program Files\Python38\lib\unittest\case.py", line 905, in _baseAssertEqual
    raise self.failureException(msg)
AssertionError: 2 != [1004]

During handling of the above exception, another exception occurred:

Traceback (most recent call last):
  File "D:\PychramCode\auto_api_test\testcases\test_recharge.py", line 83, in test_recharge
    self.assertEqual(expected["code"], jsonpath(res, "$..code"))
  File "C:\Program Files\JetBrains\PyCharm Community Edition 2019.3.4\plugins\python-ce\helpers\pycharm\teamcity\diff_tools.py", line 38, in _patched_equals
    raise error
teamcity.diff_tools.EqualsAssertionError:  :: 2 != [1004]
2020-06-21 20:36:24,213 -- [test_recharge.py-->line:92] - DEBUG: ----用例充值金额为0执行完成-------
2020-06-21 20:36:24,213 -- [test_recharge.py-->line:93] - ERROR:  :: 2 != [1004]
Traceback (most recent call last):
  File "C:\Program Files\JetBrains\PyCharm Community Edition 2019.3.4\plugins\python-ce\helpers\pycharm\teamcity\diff_tools.py", line 32, in _patched_equals
    old(self, first, second, msg)
  File "D:\Program Files\Python38\lib\unittest\case.py", line 912, in assertEqual
    assertion_func(first, second, msg=msg)
  File "D:\Program Files\Python38\lib\unittest\case.py", line 905, in _baseAssertEqual
    raise self.failureException(msg)
AssertionError: 2 != [1004]

During handling of the above exception, another exception occurred:

Traceback (most recent call last):
  File "D:\PychramCode\auto_api_test\testcases\test_recharge.py", line 83, in test_recharge
    self.assertEqual(expected["code"], jsonpath(res, "$..code"))
  File "C:\Program Files\JetBrains\PyCharm Community Edition 2019.3.4\plugins\python-ce\helpers\pycharm\teamcity\diff_tools.py", line 38, in _patched_equals
    raise error
teamcity.diff_tools.EqualsAssertionError:  :: 2 != [1004]
2020-06-21 20:36:24,413 -- [test_recharge.py-->line:92] - DEBUG: ----用例充值金额为负数执行完成-------
2020-06-21 20:36:24,413 -- [test_recharge.py-->line:93] - ERROR:  :: 2 != [1004]
Traceback (most recent call last):
  File "C:\Program Files\JetBrains\PyCharm Community Edition 2019.3.4\plugins\python-ce\helpers\pycharm\teamcity\diff_tools.py", line 32, in _patched_equals
    old(self, first, second, msg)
  File "D:\Program Files\Python38\lib\unittest\case.py", line 912, in assertEqual
    assertion_func(first, second, msg=msg)
  File "D:\Program Files\Python38\lib\unittest\case.py", line 905, in _baseAssertEqual
    raise self.failureException(msg)
AssertionError: 2 != [1004]

During handling of the above exception, another exception occurred:

Traceback (most recent call last):
  File "D:\PychramCode\auto_api_test\testcases\test_recharge.py", line 83, in test_recharge
    self.assertEqual(expected["code"], jsonpath(res, "$..code"))
  File "C:\Program Files\JetBrains\PyCharm Community Edition 2019.3.4\plugins\python-ce\helpers\pycharm\teamcity\diff_tools.py", line 38, in _patched_equals
    raise error
teamcity.diff_tools.EqualsAssertionError:  :: 2 != [1004]
2020-06-21 20:36:24,580 -- [test_recharge.py-->line:92] - DEBUG: ----用例充值金额为空执行完成-------
2020-06-21 20:36:24,580 -- [test_recharge.py-->line:93] - ERROR:  :: 1 != [1004]
Traceback (most recent call last):
  File "C:\Program Files\JetBrains\PyCharm Community Edition 2019.3.4\plugins\python-ce\helpers\pycharm\teamcity\diff_tools.py", line 32, in _patched_equals
    old(self, first, second, msg)
  File "D:\Program Files\Python38\lib\unittest\case.py", line 912, in assertEqual
    assertion_func(first, second, msg=msg)
  File "D:\Program Files\Python38\lib\unittest\case.py", line 905, in _baseAssertEqual
    raise self.failureException(msg)
AssertionError: 1 != [1004]

During handling of the above exception, another exception occurred:

Traceback (most recent call last):
  File "D:\PychramCode\auto_api_test\testcases\test_recharge.py", line 83, in test_recharge
    self.assertEqual(expected["code"], jsonpath(res, "$..code"))
  File "C:\Program Files\JetBrains\PyCharm Community Edition 2019.3.4\plugins\python-ce\helpers\pycharm\teamcity\diff_tools.py", line 38, in _patched_equals
    raise error
teamcity.diff_tools.EqualsAssertionError:  :: 1 != [1004]
2020-06-21 20:36:24,762 -- [test_recharge.py-->line:92] - DEBUG: ----用例充值金额-3位小数执行完成-------
2020-06-21 20:36:24,762 -- [test_recharge.py-->line:93] - ERROR:  :: 2 != [1004]
Traceback (most recent call last):
  File "C:\Program Files\JetBrains\PyCharm Community Edition 2019.3.4\plugins\python-ce\helpers\pycharm\teamcity\diff_tools.py", line 32, in _patched_equals
    old(self, first, second, msg)
  File "D:\Program Files\Python38\lib\unittest\case.py", line 912, in assertEqual
    assertion_func(first, second, msg=msg)
  File "D:\Program Files\Python38\lib\unittest\case.py", line 905, in _baseAssertEqual
    raise self.failureException(msg)
AssertionError: 2 != [1004]

During handling of the above exception, another exception occurred:

Traceback (most recent call last):
  File "D:\PychramCode\auto_api_test\testcases\test_recharge.py", line 83, in test_recharge
    self.assertEqual(expected["code"], jsonpath(res, "$..code"))
  File "C:\Program Files\JetBrains\PyCharm Community Edition 2019.3.4\plugins\python-ce\helpers\pycharm\teamcity\diff_tools.py", line 38, in _patched_equals
    raise error
teamcity.diff_tools.EqualsAssertionError:  :: 2 != [1004]
2020-06-21 20:36:24,929 -- [test_recharge.py-->line:92] - DEBUG: ----用例充值金额-大于50万执行完成-------
2020-06-21 20:36:24,930 -- [test_recharge.py-->line:93] - ERROR:  :: 2 != [1004]
Traceback (most recent call last):
  File "C:\Program Files\JetBrains\PyCharm Community Edition 2019.3.4\plugins\python-ce\helpers\pycharm\teamcity\diff_tools.py", line 32, in _patched_equals
    old(self, first, second, msg)
  File "D:\Program Files\Python38\lib\unittest\case.py", line 912, in assertEqual
    assertion_func(first, second, msg=msg)
  File "D:\Program Files\Python38\lib\unittest\case.py", line 905, in _baseAssertEqual
    raise self.failureException(msg)
AssertionError: 2 != [1004]

During handling of the above exception, another exception occurred:

Traceback (most recent call last):
  File "D:\PychramCode\auto_api_test\testcases\test_recharge.py", line 83, in test_recharge
    self.assertEqual(expected["code"], jsonpath(res, "$..code"))
  File "C:\Program Files\JetBrains\PyCharm Community Edition 2019.3.4\plugins\python-ce\helpers\pycharm\teamcity\diff_tools.py", line 38, in _patched_equals
    raise error
teamcity.diff_tools.EqualsAssertionError:  :: 2 != [1004]
2020-06-21 20:36:25,091 -- [test_recharge.py-->line:92] - DEBUG: ----用例充值金额-非数字执行完成-------
2020-06-21 20:36:25,091 -- [test_recharge.py-->line:93] - ERROR:  :: 2 != [1004]
Traceback (most recent call last):
  File "C:\Program Files\JetBrains\PyCharm Community Edition 2019.3.4\plugins\python-ce\helpers\pycharm\teamcity\diff_tools.py", line 32, in _patched_equals
    old(self, first, second, msg)
  File "D:\Program Files\Python38\lib\unittest\case.py", line 912, in assertEqual
    assertion_func(first, second, msg=msg)
  File "D:\Program Files\Python38\lib\unittest\case.py", line 905, in _baseAssertEqual
    raise self.failureException(msg)
AssertionError: 2 != [1004]

During handling of the above exception, another exception occurred:

Traceback (most recent call last):
  File "D:\PychramCode\auto_api_test\testcases\test_recharge.py", line 83, in test_recharge
    self.assertEqual(expected["code"], jsonpath(res, "$..code"))
  File "C:\Program Files\JetBrains\PyCharm Community Edition 2019.3.4\plugins\python-ce\helpers\pycharm\teamcity\diff_tools.py", line 38, in _patched_equals
    raise error
teamcity.diff_tools.EqualsAssertionError:  :: 2 != [1004]
2020-06-21 20:39:38,937 -- [test_recharge.py-->line:93] - DEBUG: ----用例充值成功-整数执行完成-------
2020-06-21 20:39:38,937 -- [test_recharge.py-->line:94] - ERROR:  :: 0 != [0]
Traceback (most recent call last):
  File "C:\Program Files\JetBrains\PyCharm Community Edition 2019.3.4\plugins\python-ce\helpers\pycharm\teamcity\diff_tools.py", line 32, in _patched_equals
    old(self, first, second, msg)
  File "D:\Program Files\Python38\lib\unittest\case.py", line 912, in assertEqual
    assertion_func(first, second, msg=msg)
  File "D:\Program Files\Python38\lib\unittest\case.py", line 905, in _baseAssertEqual
    raise self.failureException(msg)
AssertionError: 0 != [0]

During handling of the above exception, another exception occurred:

Traceback (most recent call last):
  File "D:\PychramCode\auto_api_test\testcases\test_recharge.py", line 84, in test_recharge
    self.assertEqual(expected["code"], jsonpath(res, "$..code"))
  File "C:\Program Files\JetBrains\PyCharm Community Edition 2019.3.4\plugins\python-ce\helpers\pycharm\teamcity\diff_tools.py", line 38, in _patched_equals
    raise error
teamcity.diff_tools.EqualsAssertionError:  :: 0 != [0]
2020-06-21 20:39:39,217 -- [test_recharge.py-->line:93] - DEBUG: ----用例充值成功-1位小数执行完成-------
2020-06-21 20:39:39,217 -- [test_recharge.py-->line:94] - ERROR:  :: 0 != [0]
Traceback (most recent call last):
  File "C:\Program Files\JetBrains\PyCharm Community Edition 2019.3.4\plugins\python-ce\helpers\pycharm\teamcity\diff_tools.py", line 32, in _patched_equals
    old(self, first, second, msg)
  File "D:\Program Files\Python38\lib\unittest\case.py", line 912, in assertEqual
    assertion_func(first, second, msg=msg)
  File "D:\Program Files\Python38\lib\unittest\case.py", line 905, in _baseAssertEqual
    raise self.failureException(msg)
AssertionError: 0 != [0]

During handling of the above exception, another exception occurred:

Traceback (most recent call last):
  File "D:\PychramCode\auto_api_test\testcases\test_recharge.py", line 84, in test_recharge
    self.assertEqual(expected["code"], jsonpath(res, "$..code"))
  File "C:\Program Files\JetBrains\PyCharm Community Edition 2019.3.4\plugins\python-ce\helpers\pycharm\teamcity\diff_tools.py", line 38, in _patched_equals
    raise error
teamcity.diff_tools.EqualsAssertionError:  :: 0 != [0]
2020-06-21 20:39:39,486 -- [test_recharge.py-->line:93] - DEBUG: ----用例充值成功-2位小数执行完成-------
2020-06-21 20:39:39,486 -- [test_recharge.py-->line:94] - ERROR:  :: 0 != [0]
Traceback (most recent call last):
  File "C:\Program Files\JetBrains\PyCharm Community Edition 2019.3.4\plugins\python-ce\helpers\pycharm\teamcity\diff_tools.py", line 32, in _patched_equals
    old(self, first, second, msg)
  File "D:\Program Files\Python38\lib\unittest\case.py", line 912, in assertEqual
    assertion_func(first, second, msg=msg)
  File "D:\Program Files\Python38\lib\unittest\case.py", line 905, in _baseAssertEqual
    raise self.failureException(msg)
AssertionError: 0 != [0]

During handling of the above exception, another exception occurred:

Traceback (most recent call last):
  File "D:\PychramCode\auto_api_test\testcases\test_recharge.py", line 84, in test_recharge
    self.assertEqual(expected["code"], jsonpath(res, "$..code"))
  File "C:\Program Files\JetBrains\PyCharm Community Edition 2019.3.4\plugins\python-ce\helpers\pycharm\teamcity\diff_tools.py", line 38, in _patched_equals
    raise error
teamcity.diff_tools.EqualsAssertionError:  :: 0 != [0]
2020-06-21 20:39:39,752 -- [test_recharge.py-->line:93] - DEBUG: ----用例充值成功-50万执行完成-------
2020-06-21 20:39:39,752 -- [test_recharge.py-->line:94] - ERROR:  :: 0 != [0]
Traceback (most recent call last):
  File "C:\Program Files\JetBrains\PyCharm Community Edition 2019.3.4\plugins\python-ce\helpers\pycharm\teamcity\diff_tools.py", line 32, in _patched_equals
    old(self, first, second, msg)
  File "D:\Program Files\Python38\lib\unittest\case.py", line 912, in assertEqual
    assertion_func(first, second, msg=msg)
  File "D:\Program Files\Python38\lib\unittest\case.py", line 905, in _baseAssertEqual
    raise self.failureException(msg)
AssertionError: 0 != [0]

During handling of the above exception, another exception occurred:

Traceback (most recent call last):
  File "D:\PychramCode\auto_api_test\testcases\test_recharge.py", line 84, in test_recharge
    self.assertEqual(expected["code"], jsonpath(res, "$..code"))
  File "C:\Program Files\JetBrains\PyCharm Community Edition 2019.3.4\plugins\python-ce\helpers\pycharm\teamcity\diff_tools.py", line 38, in _patched_equals
    raise error
teamcity.diff_tools.EqualsAssertionError:  :: 0 != [0]
2020-06-21 20:39:39,879 -- [test_recharge.py-->line:93] - DEBUG: ----用例会员id为空执行完成-------
2020-06-21 20:39:39,879 -- [test_recharge.py-->line:94] - ERROR:  :: 1 != [1]
Traceback (most recent call last):
  File "C:\Program Files\JetBrains\PyCharm Community Edition 2019.3.4\plugins\python-ce\helpers\pycharm\teamcity\diff_tools.py", line 32, in _patched_equals
    old(self, first, second, msg)
  File "D:\Program Files\Python38\lib\unittest\case.py", line 912, in assertEqual
    assertion_func(first, second, msg=msg)
  File "D:\Program Files\Python38\lib\unittest\case.py", line 905, in _baseAssertEqual
    raise self.failureException(msg)
AssertionError: 1 != [1]

During handling of the above exception, another exception occurred:

Traceback (most recent call last):
  File "D:\PychramCode\auto_api_test\testcases\test_recharge.py", line 84, in test_recharge
    self.assertEqual(expected["code"], jsonpath(res, "$..code"))
  File "C:\Program Files\JetBrains\PyCharm Community Edition 2019.3.4\plugins\python-ce\helpers\pycharm\teamcity\diff_tools.py", line 38, in _patched_equals
    raise error
teamcity.diff_tools.EqualsAssertionError:  :: 1 != [1]
2020-06-21 20:39:39,996 -- [test_recharge.py-->line:93] - DEBUG: ----用例id不是当前登录的用户执行完成-------
2020-06-21 20:39:39,996 -- [test_recharge.py-->line:94] - ERROR:  :: 1007 != [1007]
Traceback (most recent call last):
  File "C:\Program Files\JetBrains\PyCharm Community Edition 2019.3.4\plugins\python-ce\helpers\pycharm\teamcity\diff_tools.py", line 32, in _patched_equals
    old(self, first, second, msg)
  File "D:\Program Files\Python38\lib\unittest\case.py", line 912, in assertEqual
    assertion_func(first, second, msg=msg)
  File "D:\Program Files\Python38\lib\unittest\case.py", line 905, in _baseAssertEqual
    raise self.failureException(msg)
AssertionError: 1007 != [1007]

During handling of the above exception, another exception occurred:

Traceback (most recent call last):
  File "D:\PychramCode\auto_api_test\testcases\test_recharge.py", line 84, in test_recharge
    self.assertEqual(expected["code"], jsonpath(res, "$..code"))
  File "C:\Program Files\JetBrains\PyCharm Community Edition 2019.3.4\plugins\python-ce\helpers\pycharm\teamcity\diff_tools.py", line 38, in _patched_equals
    raise error
teamcity.diff_tools.EqualsAssertionError:  :: 1007 != [1007]
2020-06-21 20:39:40,119 -- [test_recharge.py-->line:93] - DEBUG: ----用例会员id为字符串执行完成-------
2020-06-21 20:39:40,119 -- [test_recharge.py-->line:94] - ERROR:  :: 2 != [0]
Traceback (most recent call last):
  File "C:\Program Files\JetBrains\PyCharm Community Edition 2019.3.4\plugins\python-ce\helpers\pycharm\teamcity\diff_tools.py", line 32, in _patched_equals
    old(self, first, second, msg)
  File "D:\Program Files\Python38\lib\unittest\case.py", line 912, in assertEqual
    assertion_func(first, second, msg=msg)
  File "D:\Program Files\Python38\lib\unittest\case.py", line 905, in _baseAssertEqual
    raise self.failureException(msg)
AssertionError: 2 != [0]

During handling of the above exception, another exception occurred:

Traceback (most recent call last):
  File "D:\PychramCode\auto_api_test\testcases\test_recharge.py", line 84, in test_recharge
    self.assertEqual(expected["code"], jsonpath(res, "$..code"))
  File "C:\Program Files\JetBrains\PyCharm Community Edition 2019.3.4\plugins\python-ce\helpers\pycharm\teamcity\diff_tools.py", line 38, in _patched_equals
    raise error
teamcity.diff_tools.EqualsAssertionError:  :: 2 != [0]
2020-06-21 20:39:40,249 -- [test_recharge.py-->line:93] - DEBUG: ----用例会员id为小数执行完成-------
2020-06-21 20:39:40,249 -- [test_recharge.py-->line:94] - ERROR:  :: 2 != [2]
Traceback (most recent call last):
  File "C:\Program Files\JetBrains\PyCharm Community Edition 2019.3.4\plugins\python-ce\helpers\pycharm\teamcity\diff_tools.py", line 32, in _patched_equals
    old(self, first, second, msg)
  File "D:\Program Files\Python38\lib\unittest\case.py", line 912, in assertEqual
    assertion_func(first, second, msg=msg)
  File "D:\Program Files\Python38\lib\unittest\case.py", line 905, in _baseAssertEqual
    raise self.failureException(msg)
AssertionError: 2 != [2]

During handling of the above exception, another exception occurred:

Traceback (most recent call last):
  File "D:\PychramCode\auto_api_test\testcases\test_recharge.py", line 84, in test_recharge
    self.assertEqual(expected["code"], jsonpath(res, "$..code"))
  File "C:\Program Files\JetBrains\PyCharm Community Edition 2019.3.4\plugins\python-ce\helpers\pycharm\teamcity\diff_tools.py", line 38, in _patched_equals
    raise error
teamcity.diff_tools.EqualsAssertionError:  :: 2 != [2]
2020-06-21 20:39:40,374 -- [test_recharge.py-->line:93] - DEBUG: ----用例充值金额为0执行完成-------
2020-06-21 20:39:40,374 -- [test_recharge.py-->line:94] - ERROR:  :: 2 != [0]
Traceback (most recent call last):
  File "C:\Program Files\JetBrains\PyCharm Community Edition 2019.3.4\plugins\python-ce\helpers\pycharm\teamcity\diff_tools.py", line 32, in _patched_equals
    old(self, first, second, msg)
  File "D:\Program Files\Python38\lib\unittest\case.py", line 912, in assertEqual
    assertion_func(first, second, msg=msg)
  File "D:\Program Files\Python38\lib\unittest\case.py", line 905, in _baseAssertEqual
    raise self.failureException(msg)
AssertionError: 2 != [0]

During handling of the above exception, another exception occurred:

Traceback (most recent call last):
  File "D:\PychramCode\auto_api_test\testcases\test_recharge.py", line 84, in test_recharge
    self.assertEqual(expected["code"], jsonpath(res, "$..code"))
  File "C:\Program Files\JetBrains\PyCharm Community Edition 2019.3.4\plugins\python-ce\helpers\pycharm\teamcity\diff_tools.py", line 38, in _patched_equals
    raise error
teamcity.diff_tools.EqualsAssertionError:  :: 2 != [0]
2020-06-21 20:39:40,515 -- [test_recharge.py-->line:93] - DEBUG: ----用例充值金额为负数执行完成-------
2020-06-21 20:39:40,515 -- [test_recharge.py-->line:94] - ERROR:  :: 2 != [2]
Traceback (most recent call last):
  File "C:\Program Files\JetBrains\PyCharm Community Edition 2019.3.4\plugins\python-ce\helpers\pycharm\teamcity\diff_tools.py", line 32, in _patched_equals
    old(self, first, second, msg)
  File "D:\Program Files\Python38\lib\unittest\case.py", line 912, in assertEqual
    assertion_func(first, second, msg=msg)
  File "D:\Program Files\Python38\lib\unittest\case.py", line 905, in _baseAssertEqual
    raise self.failureException(msg)
AssertionError: 2 != [2]

During handling of the above exception, another exception occurred:

Traceback (most recent call last):
  File "D:\PychramCode\auto_api_test\testcases\test_recharge.py", line 84, in test_recharge
    self.assertEqual(expected["code"], jsonpath(res, "$..code"))
  File "C:\Program Files\JetBrains\PyCharm Community Edition 2019.3.4\plugins\python-ce\helpers\pycharm\teamcity\diff_tools.py", line 38, in _patched_equals
    raise error
teamcity.diff_tools.EqualsAssertionError:  :: 2 != [2]
2020-06-21 20:39:40,638 -- [test_recharge.py-->line:93] - DEBUG: ----用例充值金额为空执行完成-------
2020-06-21 20:39:40,638 -- [test_recharge.py-->line:94] - ERROR:  :: 1 != [2]
Traceback (most recent call last):
  File "C:\Program Files\JetBrains\PyCharm Community Edition 2019.3.4\plugins\python-ce\helpers\pycharm\teamcity\diff_tools.py", line 32, in _patched_equals
    old(self, first, second, msg)
  File "D:\Program Files\Python38\lib\unittest\case.py", line 912, in assertEqual
    assertion_func(first, second, msg=msg)
  File "D:\Program Files\Python38\lib\unittest\case.py", line 905, in _baseAssertEqual
    raise self.failureException(msg)
AssertionError: 1 != [2]

During handling of the above exception, another exception occurred:

Traceback (most recent call last):
  File "D:\PychramCode\auto_api_test\testcases\test_recharge.py", line 84, in test_recharge
    self.assertEqual(expected["code"], jsonpath(res, "$..code"))
  File "C:\Program Files\JetBrains\PyCharm Community Edition 2019.3.4\plugins\python-ce\helpers\pycharm\teamcity\diff_tools.py", line 38, in _patched_equals
    raise error
teamcity.diff_tools.EqualsAssertionError:  :: 1 != [2]
2020-06-21 20:39:40,766 -- [test_recharge.py-->line:93] - DEBUG: ----用例充值金额-3位小数执行完成-------
2020-06-21 20:39:40,766 -- [test_recharge.py-->line:94] - ERROR:  :: 2 != [2]
Traceback (most recent call last):
  File "C:\Program Files\JetBrains\PyCharm Community Edition 2019.3.4\plugins\python-ce\helpers\pycharm\teamcity\diff_tools.py", line 32, in _patched_equals
    old(self, first, second, msg)
  File "D:\Program Files\Python38\lib\unittest\case.py", line 912, in assertEqual
    assertion_func(first, second, msg=msg)
  File "D:\Program Files\Python38\lib\unittest\case.py", line 905, in _baseAssertEqual
    raise self.failureException(msg)
AssertionError: 2 != [2]

During handling of the above exception, another exception occurred:

Traceback (most recent call last):
  File "D:\PychramCode\auto_api_test\testcases\test_recharge.py", line 84, in test_recharge
    self.assertEqual(expected["code"], jsonpath(res, "$..code"))
  File "C:\Program Files\JetBrains\PyCharm Community Edition 2019.3.4\plugins\python-ce\helpers\pycharm\teamcity\diff_tools.py", line 38, in _patched_equals
    raise error
teamcity.diff_tools.EqualsAssertionError:  :: 2 != [2]
2020-06-21 20:39:40,882 -- [test_recharge.py-->line:93] - DEBUG: ----用例充值金额-大于50万执行完成-------
2020-06-21 20:39:40,882 -- [test_recharge.py-->line:94] - ERROR:  :: 2 != [2]
Traceback (most recent call last):
  File "C:\Program Files\JetBrains\PyCharm Community Edition 2019.3.4\plugins\python-ce\helpers\pycharm\teamcity\diff_tools.py", line 32, in _patched_equals
    old(self, first, second, msg)
  File "D:\Program Files\Python38\lib\unittest\case.py", line 912, in assertEqual
    assertion_func(first, second, msg=msg)
  File "D:\Program Files\Python38\lib\unittest\case.py", line 905, in _baseAssertEqual
    raise self.failureException(msg)
AssertionError: 2 != [2]

During handling of the above exception, another exception occurred:

Traceback (most recent call last):
  File "D:\PychramCode\auto_api_test\testcases\test_recharge.py", line 84, in test_recharge
    self.assertEqual(expected["code"], jsonpath(res, "$..code"))
  File "C:\Program Files\JetBrains\PyCharm Community Edition 2019.3.4\plugins\python-ce\helpers\pycharm\teamcity\diff_tools.py", line 38, in _patched_equals
    raise error
teamcity.diff_tools.EqualsAssertionError:  :: 2 != [2]
2020-06-21 20:39:41,006 -- [test_recharge.py-->line:93] - DEBUG: ----用例充值金额-非数字执行完成-------
2020-06-21 20:39:41,006 -- [test_recharge.py-->line:94] - ERROR:  :: 2 != [2]
Traceback (most recent call last):
  File "C:\Program Files\JetBrains\PyCharm Community Edition 2019.3.4\plugins\python-ce\helpers\pycharm\teamcity\diff_tools.py", line 32, in _patched_equals
    old(self, first, second, msg)
  File "D:\Program Files\Python38\lib\unittest\case.py", line 912, in assertEqual
    assertion_func(first, second, msg=msg)
  File "D:\Program Files\Python38\lib\unittest\case.py", line 905, in _baseAssertEqual
    raise self.failureException(msg)
AssertionError: 2 != [2]

During handling of the above exception, another exception occurred:

Traceback (most recent call last):
  File "D:\PychramCode\auto_api_test\testcases\test_recharge.py", line 84, in test_recharge
    self.assertEqual(expected["code"], jsonpath(res, "$..code"))
  File "C:\Program Files\JetBrains\PyCharm Community Edition 2019.3.4\plugins\python-ce\helpers\pycharm\teamcity\diff_tools.py", line 38, in _patched_equals
    raise error
teamcity.diff_tools.EqualsAssertionError:  :: 2 != [2]
2020-06-21 20:41:22,380 -- [test_recharge.py-->line:99] - INFO: ---用例充值成功-整数执行完成---------
2020-06-21 20:41:22,654 -- [test_recharge.py-->line:99] - INFO: ---用例充值成功-1位小数执行完成---------
2020-06-21 20:41:22,923 -- [test_recharge.py-->line:99] - INFO: ---用例充值成功-2位小数执行完成---------
2020-06-21 20:41:23,182 -- [test_recharge.py-->line:99] - INFO: ---用例充值成功-50万执行完成---------
2020-06-21 20:41:23,298 -- [test_recharge.py-->line:99] - INFO: ---用例会员id为空执行完成---------
2020-06-21 20:41:23,423 -- [test_recharge.py-->line:99] - INFO: ---用例id不是当前登录的用户执行完成---------
2020-06-21 20:41:23,556 -- [test_recharge.py-->line:93] - DEBUG: ----用例会员id为字符串执行完成-------
2020-06-21 20:41:23,556 -- [test_recharge.py-->line:94] - ERROR:  :: 2 != 0
Traceback (most recent call last):
  File "C:\Program Files\JetBrains\PyCharm Community Edition 2019.3.4\plugins\python-ce\helpers\pycharm\teamcity\diff_tools.py", line 32, in _patched_equals
    old(self, first, second, msg)
  File "D:\Program Files\Python38\lib\unittest\case.py", line 912, in assertEqual
    assertion_func(first, second, msg=msg)
  File "D:\Program Files\Python38\lib\unittest\case.py", line 905, in _baseAssertEqual
    raise self.failureException(msg)
AssertionError: 2 != 0

During handling of the above exception, another exception occurred:

Traceback (most recent call last):
  File "D:\PychramCode\auto_api_test\testcases\test_recharge.py", line 84, in test_recharge
    self.assertEqual(expected["code"], jsonpath(res, "$..code")[0])
  File "C:\Program Files\JetBrains\PyCharm Community Edition 2019.3.4\plugins\python-ce\helpers\pycharm\teamcity\diff_tools.py", line 38, in _patched_equals
    raise error
teamcity.diff_tools.EqualsAssertionError:  :: 2 != 0
2020-06-21 20:41:23,673 -- [test_recharge.py-->line:99] - INFO: ---用例会员id为小数执行完成---------
2020-06-21 20:41:23,796 -- [test_recharge.py-->line:93] - DEBUG: ----用例充值金额为0执行完成-------
2020-06-21 20:41:23,796 -- [test_recharge.py-->line:94] - ERROR:  :: 2 != 0
Traceback (most recent call last):
  File "C:\Program Files\JetBrains\PyCharm Community Edition 2019.3.4\plugins\python-ce\helpers\pycharm\teamcity\diff_tools.py", line 32, in _patched_equals
    old(self, first, second, msg)
  File "D:\Program Files\Python38\lib\unittest\case.py", line 912, in assertEqual
    assertion_func(first, second, msg=msg)
  File "D:\Program Files\Python38\lib\unittest\case.py", line 905, in _baseAssertEqual
    raise self.failureException(msg)
AssertionError: 2 != 0

During handling of the above exception, another exception occurred:

Traceback (most recent call last):
  File "D:\PychramCode\auto_api_test\testcases\test_recharge.py", line 84, in test_recharge
    self.assertEqual(expected["code"], jsonpath(res, "$..code")[0])
  File "C:\Program Files\JetBrains\PyCharm Community Edition 2019.3.4\plugins\python-ce\helpers\pycharm\teamcity\diff_tools.py", line 38, in _patched_equals
    raise error
teamcity.diff_tools.EqualsAssertionError:  :: 2 != 0
2020-06-21 20:41:23,937 -- [test_recharge.py-->line:99] - INFO: ---用例充值金额为负数执行完成---------
2020-06-21 20:41:24,058 -- [test_recharge.py-->line:93] - DEBUG: ----用例充值金额为空执行完成-------
2020-06-21 20:41:24,058 -- [test_recharge.py-->line:94] - ERROR:  :: 1 != 2
Traceback (most recent call last):
  File "C:\Program Files\JetBrains\PyCharm Community Edition 2019.3.4\plugins\python-ce\helpers\pycharm\teamcity\diff_tools.py", line 32, in _patched_equals
    old(self, first, second, msg)
  File "D:\Program Files\Python38\lib\unittest\case.py", line 912, in assertEqual
    assertion_func(first, second, msg=msg)
  File "D:\Program Files\Python38\lib\unittest\case.py", line 905, in _baseAssertEqual
    raise self.failureException(msg)
AssertionError: 1 != 2

During handling of the above exception, another exception occurred:

Traceback (most recent call last):
  File "D:\PychramCode\auto_api_test\testcases\test_recharge.py", line 84, in test_recharge
    self.assertEqual(expected["code"], jsonpath(res, "$..code")[0])
  File "C:\Program Files\JetBrains\PyCharm Community Edition 2019.3.4\plugins\python-ce\helpers\pycharm\teamcity\diff_tools.py", line 38, in _patched_equals
    raise error
teamcity.diff_tools.EqualsAssertionError:  :: 1 != 2
2020-06-21 20:41:24,184 -- [test_recharge.py-->line:99] - INFO: ---用例充值金额-3位小数执行完成---------
2020-06-21 20:41:24,305 -- [test_recharge.py-->line:99] - INFO: ---用例充值金额-大于50万执行完成---------
2020-06-21 20:41:24,430 -- [test_recharge.py-->line:99] - INFO: ---用例充值金额-非数字执行完成---------
2020-06-21 20:41:39,882 -- [test_recharge.py-->line:99] - INFO: ---用例充值成功-整数执行完成---------
2020-06-21 20:41:40,184 -- [test_recharge.py-->line:99] - INFO: ---用例充值成功-1位小数执行完成---------
2020-06-21 20:41:40,488 -- [test_recharge.py-->line:99] - INFO: ---用例充值成功-2位小数执行完成---------
2020-06-21 20:41:40,788 -- [test_recharge.py-->line:99] - INFO: ---用例充值成功-50万执行完成---------
2020-06-21 20:41:40,936 -- [test_recharge.py-->line:99] - INFO: ---用例会员id为空执行完成---------
2020-06-21 20:41:41,081 -- [test_recharge.py-->line:99] - INFO: ---用例id不是当前登录的用户执行完成---------
2020-06-21 20:41:41,241 -- [test_recharge.py-->line:93] - DEBUG: ----用例会员id为字符串执行完成-------
2020-06-21 20:41:41,241 -- [test_recharge.py-->line:94] - ERROR:  :: 2 != 0
Traceback (most recent call last):
  File "C:\Program Files\JetBrains\PyCharm Community Edition 2019.3.4\plugins\python-ce\helpers\pycharm\teamcity\diff_tools.py", line 32, in _patched_equals
    old(self, first, second, msg)
  File "D:\Program Files\Python38\lib\unittest\case.py", line 912, in assertEqual
    assertion_func(first, second, msg=msg)
  File "D:\Program Files\Python38\lib\unittest\case.py", line 905, in _baseAssertEqual
    raise self.failureException(msg)
AssertionError: 2 != 0

During handling of the above exception, another exception occurred:

Traceback (most recent call last):
  File "D:\PychramCode\auto_api_test\testcases\test_recharge.py", line 84, in test_recharge
    self.assertEqual(expected["code"], jsonpath(res, "$..code")[0])
  File "C:\Program Files\JetBrains\PyCharm Community Edition 2019.3.4\plugins\python-ce\helpers\pycharm\teamcity\diff_tools.py", line 38, in _patched_equals
    raise error
teamcity.diff_tools.EqualsAssertionError:  :: 2 != 0
2020-06-21 20:41:41,388 -- [test_recharge.py-->line:99] - INFO: ---用例会员id为小数执行完成---------
2020-06-21 20:41:41,533 -- [test_recharge.py-->line:93] - DEBUG: ----用例充值金额为0执行完成-------
2020-06-21 20:41:41,533 -- [test_recharge.py-->line:94] - ERROR:  :: 2 != 0
Traceback (most recent call last):
  File "C:\Program Files\JetBrains\PyCharm Community Edition 2019.3.4\plugins\python-ce\helpers\pycharm\teamcity\diff_tools.py", line 32, in _patched_equals
    old(self, first, second, msg)
  File "D:\Program Files\Python38\lib\unittest\case.py", line 912, in assertEqual
    assertion_func(first, second, msg=msg)
  File "D:\Program Files\Python38\lib\unittest\case.py", line 905, in _baseAssertEqual
    raise self.failureException(msg)
AssertionError: 2 != 0

During handling of the above exception, another exception occurred:

Traceback (most recent call last):
  File "D:\PychramCode\auto_api_test\testcases\test_recharge.py", line 84, in test_recharge
    self.assertEqual(expected["code"], jsonpath(res, "$..code")[0])
  File "C:\Program Files\JetBrains\PyCharm Community Edition 2019.3.4\plugins\python-ce\helpers\pycharm\teamcity\diff_tools.py", line 38, in _patched_equals
    raise error
teamcity.diff_tools.EqualsAssertionError:  :: 2 != 0
2020-06-21 20:41:41,685 -- [test_recharge.py-->line:99] - INFO: ---用例充值金额为负数执行完成---------
2020-06-21 20:41:41,835 -- [test_recharge.py-->line:93] - DEBUG: ----用例充值金额为空执行完成-------
2020-06-21 20:41:41,835 -- [test_recharge.py-->line:94] - ERROR:  :: 1 != 2
Traceback (most recent call last):
  File "C:\Program Files\JetBrains\PyCharm Community Edition 2019.3.4\plugins\python-ce\helpers\pycharm\teamcity\diff_tools.py", line 32, in _patched_equals
    old(self, first, second, msg)
  File "D:\Program Files\Python38\lib\unittest\case.py", line 912, in assertEqual
    assertion_func(first, second, msg=msg)
  File "D:\Program Files\Python38\lib\unittest\case.py", line 905, in _baseAssertEqual
    raise self.failureException(msg)
AssertionError: 1 != 2

During handling of the above exception, another exception occurred:

Traceback (most recent call last):
  File "D:\PychramCode\auto_api_test\testcases\test_recharge.py", line 84, in test_recharge
    self.assertEqual(expected["code"], jsonpath(res, "$..code")[0])
  File "C:\Program Files\JetBrains\PyCharm Community Edition 2019.3.4\plugins\python-ce\helpers\pycharm\teamcity\diff_tools.py", line 38, in _patched_equals
    raise error
teamcity.diff_tools.EqualsAssertionError:  :: 1 != 2
2020-06-21 20:41:41,976 -- [test_recharge.py-->line:99] - INFO: ---用例充值金额-3位小数执行完成---------
2020-06-21 20:41:42,116 -- [test_recharge.py-->line:99] - INFO: ---用例充值金额-大于50万执行完成---------
2020-06-21 20:41:42,274 -- [test_recharge.py-->line:99] - INFO: ---用例充值金额-非数字执行完成---------
2020-06-21 20:42:57,986 -- [run_test.py-->line:11] - INFO: --------------------开始执行案例-------------------
2020-06-21 20:43:02,142 -- [test_login.py-->line:62] - INFO: 用例---登录成功----执行通过
2020-06-21 20:43:02,284 -- [test_login.py-->line:62] - INFO: 用例---手机号为空----执行通过
2020-06-21 20:43:02,422 -- [test_login.py-->line:62] - INFO: 用例---密码为空----执行通过
2020-06-21 20:43:02,598 -- [test_login.py-->line:62] - INFO: 用例---手机号未注册----执行通过
2020-06-21 20:43:02,775 -- [test_login.py-->line:62] - INFO: 用例---密码错误----执行通过
2020-06-21 20:43:02,911 -- [test_login.py-->line:62] - INFO: 用例---手机号格式错误----执行通过
2020-06-21 20:43:03,295 -- [test_recharge.py-->line:99] - INFO: ---用例充值成功-整数执行完成---------
2020-06-21 20:43:03,594 -- [test_recharge.py-->line:99] - INFO: ---用例充值成功-1位小数执行完成---------
2020-06-21 20:43:03,876 -- [test_recharge.py-->line:99] - INFO: ---用例充值成功-2位小数执行完成---------
2020-06-21 20:43:04,163 -- [test_recharge.py-->line:99] - INFO: ---用例充值成功-50万执行完成---------
2020-06-21 20:43:04,303 -- [test_recharge.py-->line:99] - INFO: ---用例会员id为空执行完成---------
2020-06-21 20:43:04,439 -- [test_recharge.py-->line:99] - INFO: ---用例id不是当前登录的用户执行完成---------
2020-06-21 20:43:04,589 -- [test_recharge.py-->line:93] - DEBUG: ----用例会员id为字符串执行完成-------
2020-06-21 20:43:04,589 -- [test_recharge.py-->line:94] - ERROR: 2 != 0
Traceback (most recent call last):
  File "D:\PychramCode\auto_api_test\testcases\test_recharge.py", line 84, in test_recharge
    self.assertEqual(expected["code"], jsonpath(res, "$..code")[0])
  File "D:\Program Files\Python38\lib\unittest\case.py", line 912, in assertEqual
    assertion_func(first, second, msg=msg)
  File "D:\Program Files\Python38\lib\unittest\case.py", line 905, in _baseAssertEqual
    raise self.failureException(msg)
AssertionError: 2 != 0
2020-06-21 20:43:04,739 -- [test_recharge.py-->line:99] - INFO: ---用例会员id为小数执行完成---------
2020-06-21 20:43:04,896 -- [test_recharge.py-->line:93] - DEBUG: ----用例充值金额为0执行完成-------
2020-06-21 20:43:04,896 -- [test_recharge.py-->line:94] - ERROR: 2 != 0
Traceback (most recent call last):
  File "D:\PychramCode\auto_api_test\testcases\test_recharge.py", line 84, in test_recharge
    self.assertEqual(expected["code"], jsonpath(res, "$..code")[0])
  File "D:\Program Files\Python38\lib\unittest\case.py", line 912, in assertEqual
    assertion_func(first, second, msg=msg)
  File "D:\Program Files\Python38\lib\unittest\case.py", line 905, in _baseAssertEqual
    raise self.failureException(msg)
AssertionError: 2 != 0
2020-06-21 20:43:05,040 -- [test_recharge.py-->line:99] - INFO: ---用例充值金额为负数执行完成---------
2020-06-21 20:43:05,187 -- [test_recharge.py-->line:93] - DEBUG: ----用例充值金额为空执行完成-------
2020-06-21 20:43:05,187 -- [test_recharge.py-->line:94] - ERROR: 1 != 2
Traceback (most recent call last):
  File "D:\PychramCode\auto_api_test\testcases\test_recharge.py", line 84, in test_recharge
    self.assertEqual(expected["code"], jsonpath(res, "$..code")[0])
  File "D:\Program Files\Python38\lib\unittest\case.py", line 912, in assertEqual
    assertion_func(first, second, msg=msg)
  File "D:\Program Files\Python38\lib\unittest\case.py", line 905, in _baseAssertEqual
    raise self.failureException(msg)
AssertionError: 1 != 2
2020-06-21 20:43:05,336 -- [test_recharge.py-->line:99] - INFO: ---用例充值金额-3位小数执行完成---------
2020-06-21 20:43:05,477 -- [test_recharge.py-->line:99] - INFO: ---用例充值金额-大于50万执行完成---------
2020-06-21 20:43:05,623 -- [test_recharge.py-->line:99] - INFO: ---用例充值金额-非数字执行完成---------
2020-06-21 20:43:05,984 -- [test_register.py-->line:72] - INFO: 用例---注册成功-带注册名----执行通过
2020-06-21 20:43:06,350 -- [test_register.py-->line:72] - INFO: 用例---成功-不带用户名----执行通过
2020-06-21 20:43:06,483 -- [test_register.py-->line:72] - INFO: 用例---不输入手机号----执行通过
2020-06-21 20:43:06,623 -- [test_register.py-->line:72] - INFO: 用例---手机号长度10位----执行通过
2020-06-21 20:43:06,763 -- [test_register.py-->line:72] - INFO: 用例---手机号长度12位----执行通过
2020-06-21 20:43:06,907 -- [test_register.py-->line:72] - INFO: 用例---手机号含有非法字符----执行通过
2020-06-21 20:43:07,079 -- [test_register.py-->line:72] - INFO: 用例---已注册过的手机号----执行通过
2020-06-21 20:43:07,225 -- [test_register.py-->line:72] - INFO: 用例---密码7位----执行通过
2020-06-21 20:43:07,371 -- [test_register.py-->line:72] - INFO: 用例---密码17位----执行通过
2020-06-21 20:43:07,512 -- [test_register.py-->line:72] - INFO: 用例---不输入密码----执行通过
2020-06-21 20:43:07,646 -- [test_register.py-->line:72] - INFO: 用例---注册名11位----执行通过
2020-06-21 20:43:07,788 -- [test_register.py-->line:72] - INFO: 用例---类型输入非0，1内容----执行通过
2020-06-21 20:43:08,156 -- [test_register.py-->line:72] - INFO: 用例---不输入类型----执行通过
2020-06-21 20:43:08,230 -- [run_test.py-->line:24] - INFO: ------------------测试案例执行结束--------------------
2020-06-21 21:32:06,562 -- [run_test.py-->line:11] - INFO: --------------------开始执行案例-------------------
2020-06-21 21:32:07,900 -- [test_login.py-->line:62] - INFO: 用例---登录成功----执行通过
2020-06-21 21:32:08,053 -- [test_login.py-->line:62] - INFO: 用例---手机号为空----执行通过
2020-06-21 21:32:08,196 -- [test_login.py-->line:62] - INFO: 用例---密码为空----执行通过
2020-06-21 21:32:08,389 -- [test_login.py-->line:62] - INFO: 用例---手机号未注册----执行通过
2020-06-21 21:32:08,594 -- [test_login.py-->line:62] - INFO: 用例---密码错误----执行通过
2020-06-21 21:32:08,763 -- [test_login.py-->line:62] - INFO: 用例---手机号格式错误----执行通过
2020-06-21 21:32:12,192 -- [test_recharge.py-->line:99] - INFO: ---用例充值成功-整数执行完成---------
2020-06-21 21:32:12,481 -- [test_recharge.py-->line:99] - INFO: ---用例充值成功-1位小数执行完成---------
2020-06-21 21:32:12,784 -- [test_recharge.py-->line:99] - INFO: ---用例充值成功-2位小数执行完成---------
2020-06-21 21:32:13,085 -- [test_recharge.py-->line:99] - INFO: ---用例充值成功-50万执行完成---------
2020-06-21 21:32:13,232 -- [test_recharge.py-->line:99] - INFO: ---用例会员id为空执行完成---------
2020-06-21 21:32:13,379 -- [test_recharge.py-->line:99] - INFO: ---用例id不是当前登录的用户执行完成---------
2020-06-21 21:32:13,542 -- [test_recharge.py-->line:93] - DEBUG: ----用例会员id为字符串执行完成-------
2020-06-21 21:32:13,543 -- [test_recharge.py-->line:94] - ERROR: 2 != 0
Traceback (most recent call last):
  File "D:\PychramCode\auto_api_test\testcases\test_recharge.py", line 84, in test_recharge
    self.assertEqual(expected["code"], jsonpath(res, "$..code")[0])
  File "D:\Program Files\Python38\lib\unittest\case.py", line 912, in assertEqual
    assertion_func(first, second, msg=msg)
  File "D:\Program Files\Python38\lib\unittest\case.py", line 905, in _baseAssertEqual
    raise self.failureException(msg)
AssertionError: 2 != 0
2020-06-21 21:32:13,710 -- [test_recharge.py-->line:99] - INFO: ---用例会员id为小数执行完成---------
2020-06-21 21:32:13,877 -- [test_recharge.py-->line:93] - DEBUG: ----用例充值金额为0执行完成-------
2020-06-21 21:32:13,877 -- [test_recharge.py-->line:94] - ERROR: 2 != 0
Traceback (most recent call last):
  File "D:\PychramCode\auto_api_test\testcases\test_recharge.py", line 84, in test_recharge
    self.assertEqual(expected["code"], jsonpath(res, "$..code")[0])
  File "D:\Program Files\Python38\lib\unittest\case.py", line 912, in assertEqual
    assertion_func(first, second, msg=msg)
  File "D:\Program Files\Python38\lib\unittest\case.py", line 905, in _baseAssertEqual
    raise self.failureException(msg)
AssertionError: 2 != 0
2020-06-21 21:32:14,045 -- [test_recharge.py-->line:99] - INFO: ---用例充值金额为负数执行完成---------
2020-06-21 21:32:14,192 -- [test_recharge.py-->line:93] - DEBUG: ----用例充值金额为空执行完成-------
2020-06-21 21:32:14,192 -- [test_recharge.py-->line:94] - ERROR: 1 != 2
Traceback (most recent call last):
  File "D:\PychramCode\auto_api_test\testcases\test_recharge.py", line 84, in test_recharge
    self.assertEqual(expected["code"], jsonpath(res, "$..code")[0])
  File "D:\Program Files\Python38\lib\unittest\case.py", line 912, in assertEqual
    assertion_func(first, second, msg=msg)
  File "D:\Program Files\Python38\lib\unittest\case.py", line 905, in _baseAssertEqual
    raise self.failureException(msg)
AssertionError: 1 != 2
2020-06-21 21:32:14,345 -- [test_recharge.py-->line:99] - INFO: ---用例充值金额-3位小数执行完成---------
2020-06-21 21:32:14,492 -- [test_recharge.py-->line:99] - INFO: ---用例充值金额-大于50万执行完成---------
2020-06-21 21:32:14,635 -- [test_recharge.py-->line:99] - INFO: ---用例充值金额-非数字执行完成---------
2020-06-21 21:32:15,019 -- [test_register.py-->line:72] - INFO: 用例---注册成功-带注册名----执行通过
2020-06-21 21:32:15,393 -- [test_register.py-->line:72] - INFO: 用例---成功-不带用户名----执行通过
2020-06-21 21:32:15,536 -- [test_register.py-->line:72] - INFO: 用例---不输入手机号----执行通过
2020-06-21 21:32:15,691 -- [test_register.py-->line:72] - INFO: 用例---手机号长度10位----执行通过
2020-06-21 21:32:15,834 -- [test_register.py-->line:72] - INFO: 用例---手机号长度12位----执行通过
2020-06-21 21:32:15,995 -- [test_register.py-->line:72] - INFO: 用例---手机号含有非法字符----执行通过
2020-06-21 21:32:16,174 -- [test_register.py-->line:72] - INFO: 用例---已注册过的手机号----执行通过
2020-06-21 21:32:16,339 -- [test_register.py-->line:72] - INFO: 用例---密码7位----执行通过
2020-06-21 21:32:16,485 -- [test_register.py-->line:72] - INFO: 用例---密码17位----执行通过
2020-06-21 21:32:16,643 -- [test_register.py-->line:72] - INFO: 用例---不输入密码----执行通过
2020-06-21 21:32:16,789 -- [test_register.py-->line:72] - INFO: 用例---注册名11位----执行通过
2020-06-21 21:32:16,933 -- [test_register.py-->line:72] - INFO: 用例---类型输入非0，1内容----执行通过
2020-06-21 21:32:17,325 -- [test_register.py-->line:72] - INFO: 用例---不输入类型----执行通过
2020-06-21 21:32:17,414 -- [run_test.py-->line:24] - INFO: ------------------测试案例执行结束--------------------
